Workbook

Sheet aapl
B1: close | C1: high | D1: low | E1: volume
A2: 45292 | B2: 100 | C2: =B2+1 -> 101 | D2: =B2-1 -> 99 | E2: 1000
A3: =A2+1 -> 45293 | B3: =B2+1 -> 101 | C3: =B3+1 -> 102 | D3: =B3-1 -> 100 | E3: 1010
A4: =A3+1 -> 45294 | B4: =B3+1 -> 102 | C4: =B4+1 -> 103 | D4: =B4-1 -> 101 | E4: 1020
A5: =A4+1 -> 45295 | B5: =B4+1 -> 103 | C5: =B5+1 -> 104 | D5: =B5-1 -> 102 | E5: 1030
A6: =A5+1 -> 45296 | B6: =B5+1 -> 104 | C6: =B6+1 -> 105 | D6: =B6-1 -> 103 | E6: 1040
A7: =A6+1 -> 45297 | B7: =B6+1 -> 105 | C7: =B7+1 -> 106 | D7: =B7-1 -> 104 | E7: 1050
A8: =A7+1 -> 45298 | B8: =B7+1 -> 106 | C8: =B8+1 -> 107 | D8: =B8-1 -> 105 | E8: 1060
A9: =A8+1 -> 45299 | B9: =B8+1 -> 107 | C9: =B9+1 -> 108 | D9: =B9-1 -> 106 | E9: 1070
A10: =A9+1 -> 45300 | B10: =B9+1 -> 108 | C10: =B10+1 -> 109 | D10: =B10-1 -> 107 | E10: 1080
A11: =A10+1 -> 45301 | B11: =B10+1 -> 109 | C11: =B11+1 -> 110 | D11: =B11-1 -> 108 | E11: 1090

Sheet tsla
B1: close | C1: high | D1: low | E1: volume
A2: 45292 | B2: 100 | C2: =B2+1 -> 101 | D2: =B2-1 -> 99 | E2: 1000
A3: =A2+1 -> 45293 | B3: 102 | C3: =B3+1 -> 103 | D3: =B3-1 -> 101 | E3: 950
A4: =A3+1 -> 45294 | B4: 101 | C4: =B4+1 -> 102 | D4: =B4-1 -> 100 | E4: 990
A5: =A4+1 -> 45295 | B5: 103 | C5: =B5+1 -> 104 | D5: =B5-1 -> 102 | E5: 1020
A6: =A5+1 -> 45296 | B6: 102 | C6: =B6+1 -> 103 | D6: =B6-1 -> 101 | E6: 1100
A7: =A6+1 -> 45297 | B7: 104 | C7: =B7+1 -> 105 | D7: =B7-1 -> 103 | E7: 900
A8: =A7+1 -> 45298 | B8: 106 | C8: =B8+1 -> 107 | D8: =B8-1 -> 105 | E8: 980
A9: =A8+1 -> 45299 | B9: 105 | C9: =B9+1 -> 106 | D9: =B9-1 -> 104 | E9: 1030
A10: =A9+1 -> 45300 | B10: 107 | C10: =B10+1 -> 108 | D10: =B10-1 -> 106 | E10: 1100
A11: =A10+1 -> 45301 | B11: 108 | C11: =B11+1 -> 109 | D11: =B11-1 -> 107 | E11: 1080
A12: =A11+1 -> 45302 | B12: 110 | C12: =B12+1 -> 111 | D12: =B12-1 -> 109 | E12: 975
A13: =A12+1 -> 45303 | B13: 109 | C13: =B13+1 -> 110 | D13: =B13-1 -> 108 | E13: 1010
A14: =A13+1 -> 45304 | B14: 111 | C14: =B14+1 -> 112 | D14: =B14-1 -> 110 | E14: 1110
... A16: =A15+1 -> 45306 | B16: 113 | C16: =B16+1 -> 114 | D16: =B16-1 -> 112 | E16: 1130

Sheet sp500
B1: close | C1: volume
A2: 45292 | B2: 100 | C2: 2000
A3: =A2+1 -> 45293 | B3: 101 | C3: 1950
A4: =A3+1 -> 45294 | B4: 102 | C4: 1990
A5: =A4+1 -> 45295 | B5: 101 | C5: 2020
A6: =A5+1 -> 45296 | B6: 102 | C6: 2100
A7: =A6+1 -> 45297 | B7: 103 | C7: 1900
A8: =A7+1 -> 45298 | B8: 104 | C8: 1980
A9: =A8+1 -> 45299 | B9: 103 | C9: 2030
A10: =A9+1 -> 45300 | B10: 104 | C10: 2100
A11: =A10+1 -> 45301 | B11: 104 | C11: 2080
A12: =A11+1 -> 45302 | B12: 105 | C12: 1975
A13: =A12+1 -> 45303 | B13: 105 | C13: 2010
A14: =A13+1 -> 45304 | B14: 106 | C14: 2110
... A16: =A15+1 -> 45306 | B16: 107 | C16: 2130

Sheet sma_5_aapl
B4: close | C4: sma_5
A5: =aapl!A2 -> 45292 | B5: =aapl!B2 -> 100 | C5: =B5 -> 100
A6: =aapl!A3 -> 45293 | B6: =aapl!B3 -> 101 | C6: =SUM(B5:B6)/2 -> 100.5
A7: =aapl!A4 -> 45294 | B7: =aapl!B4 -> 102 | C7: =SUM(B5:B7)/3 -> 101
A8: =aapl!A5 -> 45295 | B8: =aapl!B5 -> 103 | C8: =SUM(B5:B8)/4 -> 101.5
A9: =aapl!A6 -> 45296 | B9: =aapl!B6 -> 104 | C9: =SUM(B5:B9)/5 -> 102
A10: =aapl!A7 -> 45297 | B10: =aapl!B7 -> 105 | C10: =SUM(B6:B10)/5 -> 103
A11: =aapl!A8 -> 45298 | B11: =aapl!B8 -> 106 | C11: =SUM(B7:B11)/5 -> 104
A12: =aapl!A9 -> 45299 | B12: =aapl!B9 -> 107 | C12: =SUM(B8:B12)/5 -> 105
A13: =aapl!A10 -> 45300 | B13: =aapl!B10 -> 108 | C13: =SUM(B9:B13)/5 -> 106
A14: =aapl!A11 -> 45301 | B14: =aapl!B11 -> 109 | C14: =SUM(B10:B14)/5 -> 107

Sheet ema_3_aapl
B1: close | C1: ewm_3
A2: =aapl!A2 -> 45292 | B2: =aapl!B2 -> 100 | C2: =B2 -> 100
A3: =A2+1 -> 45293 | B3: =aapl!B3 -> 101 | C3: =$B$15*B3+(1-$B$15)*C2 -> 100.5
A4: =A3+1 -> 45294 | B4: =aapl!B4 -> 102 | C4: =$B$15*B4+(1-$B$15)*C3 -> 101.25
A5: =A4+1 -> 45295 | B5: =aapl!B5 -> 103 | C5: =$B$15*B5+(1-$B$15)*C4 -> 102.125
A6: =A5+1 -> 45296 | B6: =aapl!B6 -> 104 | C6: =$B$15*B6+(1-$B$15)*C5 -> 103.0625
A7: =A6+1 -> 45297 | B7: =aapl!B7 -> 105 | C7: =$B$15*B7+(1-$B$15)*C6 -> 104.03125
A8: =A7+1 -> 45298 | B8: =aapl!B8 -> 106 | C8: =$B$15*B8+(1-$B$15)*C7 -> 105.01562
A9: =A8+1 -> 45299 | B9: =aapl!B9 -> 107 | C9: =$B$15*B9+(1-$B$15)*C8 -> 106.00781
A10: =A9+1 -> 45300 | B10: =aapl!B10 -> 108 | C10: =$B$15*B10+(1-$B$15)*C9 -> 107.00391
A11: =A10+1 -> 45301 | B11: =aapl!B11 -> 109 | C11: =$B$15*B11+(1-$B$15)*C10 -> 108.00195
A14: span | B14: 3
A15: alpha | B15: =2/(B14+1) -> 0.5 | D15: EWM_t = alpha * Price_t + (1 - alpha) * EWM_{t-1}

Sheet macd_12_26_tsla
B1: close | C1: ema_12 | D1: ema_26 | E1: macd_line | F1: signal_line | G1: hist
A2: =tsla!A2 -> 45292 | B2: =tsla!B2 -> 100 | C2: =B2 -> 100 | D2: =B2 -> 100 | E2: =C2-D2 -> 0 | F2: =E2 -> 0 | G2: =E2-F2 -> 0
A3: =tsla!A3 -> 45293 | B3: =tsla!B3 -> 102 | C3: =C$19*$B3+(1-C$19)*$C2 -> 100.30769 | D3: =D$19*$B3+(1-D$19)*$D2 -> 100.14815 | E3: =C3-D3 -> 0.15954416 | F3: =F$19*$E3+(1-F$19)*$F2 -> 0.031908832 | G3: =E3-F3 -> 0.12763533
A4: =tsla!A4 -> 45294 | B4: =tsla!B4 -> 101 | C4: =C$19*$B4+(1-C$19)*$C3 -> 100.4142 | D4: =D$19*$B4+(1-D$19)*$D3 -> 100.21125 | E4: =C4-D4 -> 0.2029529 | F4: =F$19*$E4+(1-F$19)*$F3 -> 0.066117645 | G4: =E4-F4 -> 0.13683525
A5: =tsla!A5 -> 45295 | B5: =tsla!B5 -> 103 | C5: =C$19*$B5+(1-C$19)*$C4 -> 100.81202 | D5: =D$19*$B5+(1-D$19)*$D4 -> 100.41782 | E5: =C5-D5 -> 0.3941939 | F5: =F$19*$E5+(1-F$19)*$F4 -> 0.1317329 | G5: =E5-F5 -> 0.262461
A6: =tsla!A6 -> 45296 | B6: =tsla!B6 -> 102 | C6: =C$19*$B6+(1-C$19)*$C5 -> 100.99478 | D6: =D$19*$B6+(1-D$19)*$D5 -> 100.53502 | E6: =C6-D6 -> 0.45976228 | F6: =F$19*$E6+(1-F$19)*$F5 -> 0.19733877 | G6: =E6-F6 -> 0.2624235
A7: =tsla!A7 -> 45297 | B7: =tsla!B7 -> 104 | C7: =C$19*$B7+(1-C$19)*$C6 -> 101.45712 | D7: =D$19*$B7+(1-D$19)*$D6 -> 100.79169 | E7: =C7-D7 -> 0.66543821 | F7: =F$19*$E7+(1-F$19)*$F6 -> 0.29095866 | G7: =E7-F7 -> 0.37447955
A8: =tsla!A8 -> 45298 | B8: =tsla!B8 -> 106 | C8: =C$19*$B8+(1-C$19)*$C7 -> 102.15603 | D8: =D$19*$B8+(1-D$19)*$D7 -> 101.17749 | E8: =C8-D8 -> 0.97854115 | F8: =F$19*$E8+(1-F$19)*$F7 -> 0.42847516 | G8: =E8-F8 -> 0.55006599
A9: =tsla!A9 -> 45299 | B9: =tsla!B9 -> 105 | C9: =C$19*$B9+(1-C$19)*$C8 -> 102.59356 | D9: =D$19*$B9+(1-D$19)*$D8 -> 101.46064 | E9: =C9-D9 -> 1.1329262 | F9: =F$19*$E9+(1-F$19)*$F8 -> 0.56936536 | G9: =E9-F9 -> 0.56356081
A10: =tsla!A10 -> 45300 | B10: =tsla!B10 -> 107 | C10: =C$19*$B10+(1-C$19)*$C9 -> 103.27148 | D10: =D$19*$B10+(1-D$19)*$D9 -> 101.87096 | E10: =C10-D10 -> 1.4005164 | F10: =F$19*$E10+(1-F$19)*$F9 -> 0.73559557 | G10: =E10-F10 -> 0.66492084
A11: =tsla!A11 -> 45301 | B11: =tsla!B11 -> 108 | C11: =C$19*$B11+(1-C$19)*$C10 -> 103.99894 | D11: =D$19*$B11+(1-D$19)*$D10 -> 102.32496 | E11: =C11-D11 -> 1.6739787 | F11: =F$19*$E11+(1-F$19)*$F10 -> 0.92327219 | G11: =E11-F11 -> 0.75070648
A12: =tsla!A12 -> 45302 | B12: =tsla!B12 -> 110 | C12: =C$19*$B12+(1-C$19)*$C11 -> 104.92218 | D12: =D$19*$B12+(1-D$19)*$D11 -> 102.89348 | E12: =C12-D12 -> 2.0286972 | F12: =F$19*$E12+(1-F$19)*$F11 -> 1.1443572 | G12: =E12-F12 -> 0.88434001
A13: =tsla!A13 -> 45303 | B13: =tsla!B13 -> 109 | C13: =C$19*$B13+(1-C$19)*$C12 -> 105.54954 | D13: =D$19*$B13+(1-D$19)*$D12 -> 103.34582 | E13: =C13-D13 -> 2.2037195 | F13: =F$19*$E13+(1-F$19)*$F12 -> 1.3562296 | G13: =E13-F13 -> 0.84748981
A14: =tsla!A14 -> 45304 | B14: =tsla!B14 -> 111 | C14: =C$19*$B14+(1-C$19)*$C13 -> 106.38807 | D14: =D$19*$B14+(1-D$19)*$D13 -> 103.91279 | E14: =C14-D14 -> 2.4752757 | F14: =F$19*$E14+(1-F$19)*$F13 -> 1.5800389 | G14: =E14-F14 -> 0.89523684
... A16: =tsla!A16 -> 45306 | B16: =tsla!B16 -> 113 | C16: =C$19*$B16+(1-C$19)*$C15 -> 108.13584 | D16: =D$19*$B16+(1-D$19)*$D15 -> 105.1406 | E16: =C16-D16 -> 2.9952384 | F16: =F$19*$E16+(1-F$19)*$F15 -> 2.0486081 | G16: =E16-F16 -> 0.94663027
A18: span | C18: 12 | D18: 26 | F18: 9
A19: alpha | C19: =2/(C18+1) -> 0.15384615 | D19: =2/(D18+1) -> 0.074074074 | F19: =2/(F18+1) -> 0.2

Sheet adx_5_tsla
B1: close | C1: high | D1: low | E1: high-low | F1: abs(high-prev_close) | G1: abs(low-prev_close) | H1: tr = max() | I1: tr14 | J1: tr14.sum() | L1: up_move | M1: down_move | N1: up_move > down_move | O1: up_move > 0 | P1: and | Q1: +DM1 | R1: +DM14 | S1: +DM14.sum() | U1: down_move > up_move | V1: down_move > 0 | W1: and | X1: -DM1 | Y1: -DM14 | Z1: -DM14.sum() | AB1: +DI | AC1: -DI | AD1: +DI - -DI | AE1: +DX + -DI | AF1: dx | AG1: adx
A2: =tsla!A2 -> 45292 | B2: =tsla!B2 -> 100 | C2: =tsla!C2 -> 101 | D2: =tsla!D2 -> 99 | E2: =C2-D2 -> 2 | H2: =MAX(E2:G2) -> 2
A3: =tsla!A3 -> 45293 | B3: =tsla!B3 -> 102 | C3: =tsla!C3 -> 103 | D3: =tsla!D3 -> 101 | E3: =C3-D3 -> 2 | F3: =ABS(C3-B2) -> 3 | G3: =ABS(D3-B2) -> 1 | H3: =MAX(E3:G3) -> 3 | L3: =C3-C2 -> 2 | M3: =D2-D3 -> -2 | N3: =L3>M3 -> TRUE | O3: =L3>0 -> TRUE | P3: =AND(N3:O3) -> TRUE | Q3: =IF(P3,L3,0) -> 2 | U3: =M3 > L3 -> FALSE | V3: =M3 > 0 -> FALSE | W3: =AND(U3:V3) -> FALSE | X3: =IF(W3,M3, 0) -> 0
A4: =tsla!A4 -> 45294 | B4: =tsla!B4 -> 101 | C4: =tsla!C4 -> 102 | D4: =tsla!D4 -> 100 | E4: =C4-D4 -> 2 | F4: =ABS(C4-B3) -> 0 | G4: =ABS(D4-B3) -> 2 | H4: =MAX(E4:G4) -> 2 | L4: =C4-C3 -> -1 | M4: =D3-D4 -> 1 | N4: =L4>M4 -> FALSE | O4: =L4>0 -> FALSE | P4: =AND(N4:O4) -> FALSE | Q4: =IF(P4,L4,0) -> 0 | U4: =M4 > L4 -> TRUE | V4: =M4 > 0 -> TRUE | W4: =AND(U4:V4) -> TRUE | X4: =IF(W4,M4, 0) -> 1
A5: =tsla!A5 -> 45295 | B5: =tsla!B5 -> 103 | C5: =tsla!C5 -> 104 | D5: =tsla!D5 -> 102 | E5: =C5-D5 -> 2 | F5: =ABS(C5-B4) -> 3 | G5: =ABS(D5-B4) -> 1 | H5: =MAX(E5:G5) -> 3 | L5: =C5-C4 -> 2 | M5: =D4-D5 -> -2 | N5: =L5>M5 -> TRUE | O5: =L5>0 -> TRUE | P5: =AND(N5:O5) -> TRUE | Q5: =IF(P5,L5,0) -> 2 | U5: =M5 > L5 -> FALSE | V5: =M5 > 0 -> FALSE | W5: =AND(U5:V5) -> FALSE | X5: =IF(W5,M5, 0) -> 0
A6: =tsla!A6 -> 45296 | B6: =tsla!B6 -> 102 | C6: =tsla!C6 -> 103 | D6: =tsla!D6 -> 101 | E6: =C6-D6 -> 2 | F6: =ABS(C6-B5) -> 0 | G6: =ABS(D6-B5) -> 2 | H6: =MAX(E6:G6) -> 2 | L6: =C6-C5 -> -1 | M6: =D5-D6 -> 1 | N6: =L6>M6 -> FALSE | O6: =L6>0 -> FALSE | P6: =AND(N6:O6) -> FALSE | Q6: =IF(P6,L6,0) -> 0 | U6: =M6 > L6 -> TRUE | V6: =M6 > 0 -> TRUE | W6: =AND(U6:V6) -> TRUE | X6: =IF(W6,M6, 0) -> 1
A7: =tsla!A7 -> 45297 | B7: =tsla!B7 -> 104 | C7: =tsla!C7 -> 105 | D7: =tsla!D7 -> 103 | E7: =C7-D7 -> 2 | F7: =ABS(C7-B6) -> 3 | G7: =ABS(D7-B6) -> 1 | H7: =MAX(E7:G7) -> 3 | L7: =C7-C6 -> 2 | M7: =D6-D7 -> -2 | N7: =L7>M7 -> TRUE | O7: =L7>0 -> TRUE | P7: =AND(N7:O7) -> TRUE | Q7: =IF(P7,L7,0) -> 2 | U7: =M7 > L7 -> FALSE | V7: =M7 > 0 -> FALSE | W7: =AND(U7:V7) -> FALSE | X7: =IF(W7,M7, 0) -> 0
A8: =tsla!A8 -> 45298 | B8: =tsla!B8 -> 106 | C8: =tsla!C8 -> 107 | D8: =tsla!D8 -> 105 | E8: =C8-D8 -> 2 | F8: =ABS(C8-B7) -> 3 | G8: =ABS(D8-B7) -> 1 | H8: =MAX(E8:G8) -> 3 | L8: =C8-C7 -> 2 | M8: =D7-D8 -> -2 | N8: =L8>M8 -> TRUE | O8: =L8>0 -> TRUE | P8: =AND(N8:O8) -> TRUE | Q8: =IF(P8,L8,0) -> 2 | U8: =M8 > L8 -> FALSE | V8: =M8 > 0 -> FALSE | W8: =AND(U8:V8) -> FALSE | X8: =IF(W8,M8, 0) -> 0
A9: =tsla!A9 -> 45299 | B9: =tsla!B9 -> 105 | C9: =tsla!C9 -> 106 | D9: =tsla!D9 -> 104 | E9: =C9-D9 -> 2 | F9: =ABS(C9-B8) -> 0 | G9: =ABS(D9-B8) -> 2 | H9: =MAX(E9:G9) -> 2 | L9: =C9-C8 -> -1 | M9: =D8-D9 -> 1 | N9: =L9>M9 -> FALSE | O9: =L9>0 -> FALSE | P9: =AND(N9:O9) -> FALSE | Q9: =IF(P9,L9,0) -> 0 | U9: =M9 > L9 -> TRUE | V9: =M9 > 0 -> TRUE | W9: =AND(U9:V9) -> TRUE | X9: =IF(W9,M9, 0) -> 1
A10: =tsla!A10 -> 45300 | B10: =tsla!B10 -> 107 | C10: =tsla!C10 -> 108 | D10: =tsla!D10 -> 106 | E10: =C10-D10 -> 2 | F10: =ABS(C10-B9) -> 3 | G10: =ABS(D10-B9) -> 1 | H10: =MAX(E10:G10) -> 3 | L10: =C10-C9 -> 2 | M10: =D9-D10 -> -2 | N10: =L10>M10 -> TRUE | O10: =L10>0 -> TRUE | P10: =AND(N10:O10) -> TRUE | Q10: =IF(P10,L10,0) -> 2 | U10: =M10 > L10 -> FALSE | V10: =M10 > 0 -> FALSE | W10: =AND(U10:V10) -> FALSE | X10: =IF(W10,M10, 0) -> 0
A11: =tsla!A11 -> 45301 | B11: =tsla!B11 -> 108 | C11: =tsla!C11 -> 109 | D11: =tsla!D11 -> 107 | E11: =C11-D11 -> 2 | F11: =ABS(C11-B10) -> 2 | G11: =ABS(D11-B10) -> 0 | H11: =MAX(E11:G11) -> 2 | L11: =C11-C10 -> 1 | M11: =D10-D11 -> -1 | N11: =L11>M11 -> TRUE | O11: =L11>0 -> TRUE | P11: =AND(N11:O11) -> TRUE | Q11: =IF(P11,L11,0) -> 1 | U11: =M11 > L11 -> FALSE | V11: =M11 > 0 -> FALSE | W11: =AND(U11:V11) -> FALSE | X11: =IF(W11,M11, 0) -> 0
A12: =tsla!A12 -> 45302 | B12: =tsla!B12 -> 110 | C12: =tsla!C12 -> 111 | D12: =tsla!D12 -> 109 | E12: =C12-D12 -> 2 | F12: =ABS(C12-B11) -> 3 | G12: =ABS(D12-B11) -> 1 | H12: =MAX(E12:G12) -> 3 | L12: =C12-C11 -> 2 | M12: =D11-D12 -> -2 | N12: =L12>M12 -> TRUE | O12: =L12>0 -> TRUE | P12: =AND(N12:O12) -> TRUE | Q12: =IF(P12,L12,0) -> 2 | U12: =M12 > L12 -> FALSE | V12: =M12 > 0 -> FALSE | W12: =AND(U12:V12) -> FALSE | X12: =IF(W12,M12, 0) -> 0
A13: =tsla!A13 -> 45303 | B13: =tsla!B13 -> 109 | C13: =tsla!C13 -> 110 | D13: =tsla!D13 -> 108 | E13: =C13-D13 -> 2 | F13: =ABS(C13-B12) -> 0 | G13: =ABS(D13-B12) -> 2 | H13: =MAX(E13:G13) -> 2 | L13: =C13-C12 -> -1 | M13: =D12-D13 -> 1 | N13: =L13>M13 -> FALSE | O13: =L13>0 -> FALSE | P13: =AND(N13:O13) -> FALSE | Q13: =IF(P13,L13,0) -> 0 | U13: =M13 > L13 -> TRUE | V13: =M13 > 0 -> TRUE | W13: =AND(U13:V13) -> TRUE | X13: =IF(W13,M13, 0) -> 1
A14: =tsla!A14 -> 45304 | B14: =tsla!B14 -> 111 | C14: =tsla!C14 -> 112 | D14: =tsla!D14 -> 110 | E14: =C14-D14 -> 2 | F14: =ABS(C14-B13) -> 3 | G14: =ABS(D14-B13) -> 1 | H14: =MAX(E14:G14) -> 3 | L14: =C14-C13 -> 2 | M14: =D13-D14 -> -2 | N14: =L14>M14 -> TRUE | O14: =L14>0 -> TRUE | P14: =AND(N14:O14) -> TRUE | Q14: =IF(P14,L14,0) -> 2 | U14: =M14 > L14 -> FALSE | V14: =M14 > 0 -> FALSE | W14: =AND(U14:V14) -> FALSE | X14: =IF(W14,M14, 0) -> 0
A15: =tsla!A15 -> 45305 | B15: =tsla!B15 -> 112 | C15: =tsla!C15 -> 113 | D15: =tsla!D15 -> 111 | E15: =C15-D15 -> 2 | F15: =ABS(C15-B14) -> 2 | G15: =ABS(D15-B14) -> 0 | H15: =MAX(E15:G15) -> 2 | I15: =AVERAGE(H2:H15) -> 2.5 | J15: =I15*14 -> 35 | L15: =C15-C14 -> 1 | M15: =D14-D15 -> -1 | N15: =L15>M15 -> TRUE | O15: =L15>0 -> TRUE | P15: =AND(N15:O15) -> TRUE | Q15: =IF(P15,L15,0) -> 1 | U15: =M15 > L15 -> FALSE | V15: =M15 > 0 -> FALSE | W15: =AND(U15:V15) -> FALSE | X15: =IF(W15,M15, 0) -> 0 | Y15: =AVERAGE(X2:X15) -> 0.30769231 | Z15: =Y15*14 -> 4.3076923
A16: =tsla!A16 -> 45306 | B16: =tsla!B16 -> 113 | C16: =tsla!C16 -> 114 | D16: =tsla!D16 -> 112 | E16: =C16-D16 -> 2 | F16: =ABS(C16-B15) -> 2 | G16: =ABS(D16-B15) -> 0 | H16: =MAX(E16:G16) -> 2 | I16: =AVERAGE(H3:H16) -> 2.5 | J16: =I16*14 -> 35 | L16: =C16-C15 -> 1 | M16: =D15-D16 -> -1 | N16: =L16>M16 -> TRUE | O16: =L16>0 -> TRUE | P16: =AND(N16:O16) -> TRUE | Q16: =IF(P16,L16,0) -> 1 | R16: =AVERAGE(Q3:Q16) -> 1.2142857 | S16: =R16*14 -> 17 | U16: =M16 > L16 -> FALSE | V16: =M16 > 0 -> FALSE | W16: =AND(U16:V16) -> FALSE | X16: =IF(W16,M16, 0) -> 0 | Y16: =AVERAGE(X3:X16) -> 0.28571429 | Z16: =Y16*14 -> 4 | AB16: =100 * (R16 / I16) -> 48.571429 | AC16: =100 * (Y16 / I16) -> 11.428571 | AD16: =AB16-AC16 -> 37.142857 | AE16: =AB16+AC16 -> 60 | AF16: =100*ABS(AD16/AE16) -> 61.904762
A17: =A16+1 -> 45307 | B17: =B2 -> 100 | C17: =C2 -> 101 | D17: =D2 -> 99 | E17: =C17-D17 -> 2 | F17: =ABS(C17-B16) -> 12 | G17: =ABS(D17-B16) -> 14 | H17: =MAX(E17:G17) -> 14 | I17: =AVERAGE(H4:H17) -> 3.2857143 | J17: =I17*14 -> 46 | L17: =C17-C16 -> -13 | M17: =D16-D17 -> 13 | N17: =L17>M17 -> FALSE | O17: =L17>0 -> FALSE | P17: =AND(N17:O17) -> FALSE | Q17: =IF(P17,L17,0) -> 0 | R17: =AVERAGE(Q4:Q17) -> 1.0714286 | S17: =R17*14 -> 15 | U17: =M17 > L17 -> TRUE | V17: =M17 > 0 -> TRUE | W17: =AND(U17:V17) -> TRUE | X17: =IF(W17,M17, 0) -> 13 | Y17: =AVERAGE(X4:X17) -> 1.2142857 | Z17: =Y17*14 -> 17 | AB17: =100 * (R17 / I17) -> 32.608696 | AC17: =100 * (Y17 / I17) -> 36.956522 | AD17: =AB17-AC17 -> -4.3478261 | AE17: =AB17+AC17 -> 69.565217 | AF17: =100*ABS(AD17/AE17) -> 6.25
A18: =A17+1 -> 45308 | B18: =B3 -> 102 | C18: =C3 -> 103 | D18: =D3 -> 101 | E18: =C18-D18 -> 2 | F18: =ABS(C18-B17) -> 3 | G18: =ABS(D18-B17) -> 1 | H18: =MAX(E18:G18) -> 3 | I18: =AVERAGE(H5:H18) -> 3.3571429 | J18: =I18*14 -> 47 | L18: =C18-C17 -> 2 | M18: =D17-D18 -> -2 | N18: =L18>M18 -> TRUE | O18: =L18>0 -> TRUE | P18: =AND(N18:O18) -> TRUE | Q18: =IF(P18,L18,0) -> 2 | R18: =AVERAGE(Q5:Q18) -> 1.2142857 | S18: =R18*14 -> 17 | U18: =M18 > L18 -> FALSE | V18: =M18 > 0 -> FALSE | W18: =AND(U18:V18) -> FALSE | X18: =IF(W18,M18, 0) -> 0 | Y18: =AVERAGE(X5:X18) -> 1.1428571 | Z18: =Y18*14 -> 16 | AB18: =100 * (R18 / I18) -> 36.170213 | AC18: =100 * (Y18 / I18) -> 34.042553 | AD18: =AB18-AC18 -> 2.1276596 | AE18: =AB18+AC18 -> 70.212766 | AF18: =100*ABS(AD18/AE18) -> 3.030303
A19: =A18+1 -> 45309 | B19: =B4 -> 101 | C19: =C4 -> 102 | D19: =D4 -> 100 | E19: =C19-D19 -> 2 | F19: =ABS(C19-B18) -> 0 | G19: =ABS(D19-B18) -> 2 | H19: =MAX(E19:G19) -> 2 | I19: =AVERAGE(H6:H19) -> 3.2857143 | J19: =I19*14 -> 46 | L19: =C19-C18 -> -1 | M19: =D18-D19 -> 1 | N19: =L19>M19 -> FALSE | O19: =L19>0 -> FALSE | P19: =AND(N19:O19) -> FALSE | Q19: =IF(P19,L19,0) -> 0 | R19: =AVERAGE(Q6:Q19) -> 1.0714286 | S19: =R19*14 -> 15 | U19: =M19 > L19 -> TRUE | V19: =M19 > 0 -> TRUE | W19: =AND(U19:V19) -> TRUE | X19: =IF(W19,M19, 0) -> 1 | Y19: =AVERAGE(X6:X19) -> 1.2142857 | Z19: =Y19*14 -> 17 | AB19: =100 * (R19 / I19) -> 32.608696 | AC19: =100 * (Y19 / I19) -> 36.956522 | AD19: =AB19-AC19 -> -4.3478261 | AE19: =AB19+AC19 -> 69.565217 | AF19: =100*ABS(AD19/AE19) -> 6.25
A20: =A19+1 -> 45310 | B20: =B5 -> 103 | C20: =C5 -> 104 | D20: =D5 -> 102 | E20: =C20-D20 -> 2 | F20: =ABS(C20-B19) -> 3 | G20: =ABS(D20-B19) -> 1 | H20: =MAX(E20:G20) -> 3 | I20: =AVERAGE(H7:H20) -> 3.3571429 | J20: =I20*14 -> 47 | L20: =C20-C19 -> 2 | M20: =D19-D20 -> -2 | N20: =L20>M20 -> TRUE | O20: =L20>0 -> TRUE | P20: =AND(N20:O20) -> TRUE | Q20: =IF(P20,L20,0) -> 2 | R20: =AVERAGE(Q7:Q20) -> 1.2142857 | S20: =R20*14 -> 17 | U20: =M20 > L20 -> FALSE | V20: =M20 > 0 -> FALSE | W20: =AND(U20:V20) -> FALSE | X20: =IF(W20,M20, 0) -> 0 | Y20: =AVERAGE(X7:X20) -> 1.1428571 | Z20: =Y20*14 -> 16 | AB20: =100 * (R20 / I20) -> 36.170213 | AC20: =100 * (Y20 / I20) -> 34.042553 | AD20: =AB20-AC20 -> 2.1276596 | AE20: =AB20+AC20 -> 70.212766 | AF20: =100*ABS(AD20/AE20) -> 3.030303
A21: =A20+1 -> 45311 | B21: =B6 -> 102 | C21: =C6 -> 103 | D21: =D6 -> 101 | E21: =C21-D21 -> 2 | F21: =ABS(C21-B20) -> 0 | G21: =ABS(D21-B20) -> 2 | H21: =MAX(E21:G21) -> 2 | I21: =AVERAGE(H8:H21) -> 3.2857143 | J21: =I21*14 -> 46 | L21: =C21-C20 -> -1 | M21: =D20-D21 -> 1 | N21: =L21>M21 -> FALSE | O21: =L21>0 -> FALSE | P21: =AND(N21:O21) -> FALSE | Q21: =IF(P21,L21,0) -> 0 | R21: =AVERAGE(Q8:Q21) -> 1.0714286 | S21: =R21*14 -> 15 | U21: =M21 > L21 -> TRUE | V21: =M21 > 0 -> TRUE | W21: =AND(U21:V21) -> TRUE | X21: =IF(W21,M21, 0) -> 1 | Y21: =AVERAGE(X8:X21) -> 1.2142857 | Z21: =Y21*14 -> 17 | AB21: =100 * (R21 / I21) -> 32.608696 | AC21: =100 * (Y21 / I21) -> 36.956522 | AD21: =AB21-AC21 -> -4.3478261 | AE21: =AB21+AC21 -> 69.565217 | AF21: =100*ABS(AD21/AE21) -> 6.25
A22: =A21+1 -> 45312 | B22: =B7 -> 104 | C22: =C7 -> 105 | D22: =D7 -> 103 | E22: =C22-D22 -> 2 | F22: =ABS(C22-B21) -> 3 | G22: =ABS(D22-B21) -> 1 | H22: =MAX(E22:G22) -> 3 | I22: =AVERAGE(H9:H22) -> 3.2857143 | J22: =I22*14 -> 46 | L22: =C22-C21 -> 2 | M22: =D21-D22 -> -2 | N22: =L22>M22 -> TRUE | O22: =L22>0 -> TRUE | P22: =AND(N22:O22) -> TRUE | Q22: =IF(P22,L22,0) -> 2 | R22: =AVERAGE(Q9:Q22) -> 1.0714286 | S22: =R22*14 -> 15 | U22: =M22 > L22 -> FALSE | V22: =M22 > 0 -> FALSE | W22: =AND(U22:V22) -> FALSE | X22: =IF(W22,M22, 0) -> 0 | Y22: =AVERAGE(X9:X22) -> 1.2142857 | Z22: =Y22*14 -> 17 | AB22: =100 * (R22 / I22) -> 32.608696 | AC22: =100 * (Y22 / I22) -> 36.956522 | AD22: =AB22-AC22 -> -4.3478261 | AE22: =AB22+AC22 -> 69.565217 | AF22: =100*ABS(AD22/AE22) -> 6.25
A23: =A22+1 -> 45313 | B23: =B8 -> 106 | C23: =C8 -> 107 | D23: =D8 -> 105 | E23: =C23-D23 -> 2 | F23: =ABS(C23-B22) -> 3 | G23: =ABS(D23-B22) -> 1 | H23: =MAX(E23:G23) -> 3 | I23: =AVERAGE(H10:H23) -> 3.3571429 | J23: =I23*14 -> 47 | L23: =C23-C22 -> 2 | M23: =D22-D23 -> -2 | N23: =L23>M23 -> TRUE | O23: =L23>0 -> TRUE | P23: =AND(N23:O23) -> TRUE | Q23: =IF(P23,L23,0) -> 2 | R23: =AVERAGE(Q10:Q23) -> 1.2142857 | S23: =R23*14 -> 17 | U23: =M23 > L23 -> FALSE | V23: =M23 > 0 -> FALSE | W23: =AND(U23:V23) -> FALSE | X23: =IF(W23,M23, 0) -> 0 | Y23: =AVERAGE(X10:X23) -> 1.1428571 | Z23: =Y23*14 -> 16 | AB23: =100 * (R23 / I23) -> 36.170213 | AC23: =100 * (Y23 / I23) -> 34.042553 | AD23: =AB23-AC23 -> 2.1276596 | AE23: =AB23+AC23 -> 70.212766 | AF23: =100*ABS(AD23/AE23) -> 3.030303
A24: =A23+1 -> 45314 | B24: =B9 -> 105 | C24: =C9 -> 106 | D24: =D9 -> 104 | E24: =C24-D24 -> 2 | F24: =ABS(C24-B23) -> 0 | G24: =ABS(D24-B23) -> 2 | H24: =MAX(E24:G24) -> 2 | I24: =AVERAGE(H11:H24) -> 3.2857143 | J24: =I24*14 -> 46 | L24: =C24-C23 -> -1 | M24: =D23-D24 -> 1 | N24: =L24>M24 -> FALSE | O24: =L24>0 -> FALSE | P24: =AND(N24:O24) -> FALSE | Q24: =IF(P24,L24,0) -> 0 | R24: =AVERAGE(Q11:Q24) -> 1.0714286 | S24: =R24*14 -> 15 | U24: =M24 > L24 -> TRUE | V24: =M24 > 0 -> TRUE | W24: =AND(U24:V24) -> TRUE | X24: =IF(W24,M24, 0) -> 1 | Y24: =AVERAGE(X11:X24) -> 1.2142857 | Z24: =Y24*14 -> 17 | AB24: =100 * (R24 / I24) -> 32.608696 | AC24: =100 * (Y24 / I24) -> 36.956522 | AD24: =AB24-AC24 -> -4.3478261 | AE24: =AB24+AC24 -> 69.565217 | AF24: =100*ABS(AD24/AE24) -> 6.25
A25: =A24+1 -> 45315 | B25: =B10 -> 107 | C25: =C10 -> 108 | D25: =D10 -> 106 | E25: =C25-D25 -> 2 | F25: =ABS(C25-B24) -> 3 | G25: =ABS(D25-B24) -> 1 | H25: =MAX(E25:G25) -> 3 | I25: =AVERAGE(H12:H25) -> 3.3571429 | J25: =I25*14 -> 47 | L25: =C25-C24 -> 2 | M25: =D24-D25 -> -2 | N25: =L25>M25 -> TRUE | O25: =L25>0 -> TRUE | P25: =AND(N25:O25) -> TRUE | Q25: =IF(P25,L25,0) -> 2 | R25: =AVERAGE(Q12:Q25) -> 1.1428571 | S25: =R25*14 -> 16 | U25: =M25 > L25 -> FALSE | V25: =M25 > 0 -> FALSE | W25: =AND(U25:V25) -> FALSE | X25: =IF(W25,M25, 0) -> 0 | Y25: =AVERAGE(X12:X25) -> 1.2142857 | Z25: =Y25*14 -> 17 | AB25: =100 * (R25 / I25) -> 34.042553 | AC25: =100 * (Y25 / I25) -> 36.170213 | AD25: =AB25-AC25 -> -2.1276596 | AE25: =AB25+AC25 -> 70.212766 | AF25: =100*ABS(AD25/AE25) -> 3.030303
A26: =A25+1 -> 45316 | B26: =B11 -> 108 | C26: =C11 -> 109 | D26: =D11 -> 107 | E26: =C26-D26 -> 2 | F26: =ABS(C26-B25) -> 2 | G26: =ABS(D26-B25) -> 0 | H26: =MAX(E26:G26) -> 2 | I26: =AVERAGE(H13:H26) -> 3.2857143 | J26: =I26*14 -> 46 | L26: =C26-C25 -> 1 | M26: =D25-D26 -> -1 | N26: =L26>M26 -> TRUE | O26: =L26>0 -> TRUE | P26: =AND(N26:O26) -> TRUE | Q26: =IF(P26,L26,0) -> 1 | R26: =AVERAGE(Q13:Q26) -> 1.0714286 | S26: =R26*14 -> 15 | U26: =M26 > L26 -> FALSE | V26: =M26 > 0 -> FALSE | W26: =AND(U26:V26) -> FALSE | X26: =IF(W26,M26, 0) -> 0 | Y26: =AVERAGE(X13:X26) -> 1.2142857 | Z26: =Y26*14 -> 17 | AB26: =100 * (R26 / I26) -> 32.608696 | AC26: =100 * (Y26 / I26) -> 36.956522 | AD26: =AB26-AC26 -> -4.3478261 | AE26: =AB26+AC26 -> 69.565217 | AF26: =100*ABS(AD26/AE26) -> 6.25
A27: =A26+1 -> 45317 | B27: =B12 -> 110 | C27: =C12 -> 111 | D27: =D12 -> 109 | E27: =C27-D27 -> 2 | F27: =ABS(C27-B26) -> 3 | G27: =ABS(D27-B26) -> 1 | H27: =MAX(E27:G27) -> 3 | I27: =AVERAGE(H14:H27) -> 3.3571429 | J27: =I27*14 -> 47 | L27: =C27-C26 -> 2 | M27: =D26-D27 -> -2 | N27: =L27>M27 -> TRUE | O27: =L27>0 -> TRUE | P27: =AND(N27:O27) -> TRUE | Q27: =IF(P27,L27,0) -> 2 | R27: =AVERAGE(Q14:Q27) -> 1.2142857 | S27: =R27*14 -> 17 | U27: =M27 > L27 -> FALSE | V27: =M27 > 0 -> FALSE | W27: =AND(U27:V27) -> FALSE | X27: =IF(W27,M27, 0) -> 0 | Y27: =AVERAGE(X14:X27) -> 1.1428571 | Z27: =Y27*14 -> 16 | AB27: =100 * (R27 / I27) -> 36.170213 | AC27: =100 * (Y27 / I27) -> 34.042553 | AD27: =AB27-AC27 -> 2.1276596 | AE27: =AB27+AC27 -> 70.212766 | AF27: =100*ABS(AD27/AE27) -> 3.030303
A28: =A27+1 -> 45318 | B28: =B13 -> 109 | C28: =C13 -> 110 | D28: =D13 -> 108 | E28: =C28-D28 -> 2 | F28: =ABS(C28-B27) -> 0 | G28: =ABS(D28-B27) -> 2 | H28: =MAX(E28:G28) -> 2 | I28: =AVERAGE(H15:H28) -> 3.2857143 | J28: =I28*14 -> 46 | L28: =C28-C27 -> -1 | M28: =D27-D28 -> 1 | N28: =L28>M28 -> FALSE | O28: =L28>0 -> FALSE | P28: =AND(N28:O28) -> FALSE | Q28: =IF(P28,L28,0) -> 0 | R28: =AVERAGE(Q15:Q28) -> 1.0714286 | S28: =R28*14 -> 15 | U28: =M28 > L28 -> TRUE | V28: =M28 > 0 -> TRUE | W28: =AND(U28:V28) -> TRUE | X28: =IF(W28,M28, 0) -> 1 | Y28: =AVERAGE(X15:X28) -> 1.2142857 | Z28: =Y28*14 -> 17 | AB28: =100 * (R28 / I28) -> 32.608696 | AC28: =100 * (Y28 / I28) -> 36.956522 | AD28: =AB28-AC28 -> -4.3478261 | AE28: =AB28+AC28 -> 69.565217 | AF28: =100*ABS(AD28/AE28) -> 6.25
A29: =A28+1 -> 45319 | B29: =B14 -> 111 | C29: =C14 -> 112 | D29: =D14 -> 110 | E29: =C29-D29 -> 2 | F29: =ABS(C29-B28) -> 3 | G29: =ABS(D29-B28) -> 1 | H29: =MAX(E29:G29) -> 3 | I29: =AVERAGE(H16:H29) -> 3.3571429 | J29: =I29*14 -> 47 | L29: =C29-C28 -> 2 | M29: =D28-D29 -> -2 | N29: =L29>M29 -> TRUE | O29: =L29>0 -> TRUE | P29: =AND(N29:O29) -> TRUE | Q29: =IF(P29,L29,0) -> 2 | R29: =AVERAGE(Q16:Q29) -> 1.1428571 | S29: =R29*14 -> 16 | U29: =M29 > L29 -> FALSE | V29: =M29 > 0 -> FALSE | W29: =AND(U29:V29) -> FALSE | X29: =IF(W29,M29, 0) -> 0 | Y29: =AVERAGE(X16:X29) -> 1.2142857 | Z29: =Y29*14 -> 17 | AB29: =100 * (R29 / I29) -> 34.042553 | AC29: =100 * (Y29 / I29) -> 36.170213 | AD29: =AB29-AC29 -> -2.1276596 | AE29: =AB29+AC29 -> 70.212766 | AF29: =100*ABS(AD29/AE29) -> 3.030303 | AG29: =AVERAGE(AF16:AF29) -> 8.84547
A30: =A29+1 -> 45320 | B30: =B15 -> 112 | C30: =C15 -> 113 | D30: =D15 -> 111 | E30: =C30-D30 -> 2 | F30: =ABS(C30-B29) -> 2 | G30: =ABS(D30-B29) -> 0 | H30: =MAX(E30:G30) -> 2 | I30: =AVERAGE(H17:H30) -> 3.3571429 | J30: =I30*14 -> 47 | L30: =C30-C29 -> 1 | M30: =D29-D30 -> -1 | N30: =L30>M30 -> TRUE | O30: =L30>0 -> TRUE | P30: =AND(N30:O30) -> TRUE | Q30: =IF(P30,L30,0) -> 1 | R30: =AVERAGE(Q17:Q30) -> 1.1428571 | S30: =R30*14 -> 16 | U30: =M30 > L30 -> FALSE | V30: =M30 > 0 -> FALSE | W30: =AND(U30:V30) -> FALSE | X30: =IF(W30,M30, 0) -> 0 | Y30: =AVERAGE(X17:X30) -> 1.2142857 | Z30: =Y30*14 -> 17 | AB30: =100 * (R30 / I30) -> 34.042553 | AC30: =100 * (Y30 / I30) -> 36.170213 | AD30: =AB30-AC30 -> -2.1276596 | AE30: =AB30+AC30 -> 70.212766 | AF30: =100*ABS(AD30/AE30) -> 3.030303 | AG30: =AVERAGE(AF17:AF30) -> 4.6401515
A31: =A30+1 -> 45321 | B31: =B16 -> 113 | C31: =C16 -> 114 | D31: =D16 -> 112 | E31: =C31-D31 -> 2 | F31: =ABS(C31-B30) -> 2 | G31: =ABS(D31-B30) -> 0 | H31: =MAX(E31:G31) -> 2 | I31: =AVERAGE(H18:H31) -> 2.5 | J31: =I31*14 -> 35 | L31: =C31-C30 -> 1 | M31: =D30-D31 -> -1 | N31: =L31>M31 -> TRUE | O31: =L31>0 -> TRUE | P31: =AND(N31:O31) -> TRUE | Q31: =IF(P31,L31,0) -> 1 | R31: =AVERAGE(Q18:Q31) -> 1.2142857 | S31: =R31*14 -> 17 | U31: =M31 > L31 -> FALSE | V31: =M31 > 0 -> FALSE | W31: =AND(U31:V31) -> FALSE | X31: =IF(W31,M31, 0) -> 0 | Y31: =AVERAGE(X18:X31) -> 0.28571429 | Z31: =Y31*14 -> 4 | AB31: =100 * (R31 / I31) -> 48.571429 | AC31: =100 * (Y31 / I31) -> 11.428571 | AD31: =AB31-AC31 -> 37.142857 | AE31: =AB31+AC31 -> 60 | AF31: =100*ABS(AD31/AE31) -> 61.904762 | AG31: =AVERAGE(AF18:AF31) -> 8.6154917
H32: correct | I32: correct | J32: correct | L32: correct | M32: correct | Q32: correct | X32: correct | Y32: correct | Z32: correct | AB32: correct | AC32: correct | AG32: correct

Sheet rsi_5_tsla
B1: close | C1: gains | D1: loss | E1: avg gain | F1: avg loss | G1: rs | H1: rsi
A2: =tsla!A2 -> 45292 | B2: =tsla!B2 -> 100
A3: =tsla!A3 -> 45293 | B3: =tsla!B3 -> 102 | C3: =IF(B3>B2, B3-B2, 0) -> 2 | D3: =IF(B3<B2,B2-B3,0) -> 0 | E3: =C3 -> 2 | F3: =D3 -> 0 | G3: =IF(F3=0,1E+307,E3/F3) -> 1e+307 | H3: =100-(100/(1+G3)) -> 100
A4: =tsla!A4 -> 45294 | B4: =tsla!B4 -> 101 | C4: =IF(B4>B3, B4-B3, 0) -> 0 | D4: =IF(B4<B3,B3-B4,0) -> 1 | E4: =$E$18*C4+(1-$E$18)*E3 -> 1.6 | F4: =$E$18*D4+(1-$E$18)*F3 -> 0.2 | G4: =IF(F4=0,1E+307,E4/F4) -> 8 | H4: =100-(100/(1+G4)) -> 88.888889
A5: =tsla!A5 -> 45295 | B5: =tsla!B5 -> 103 | C5: =IF(B5>B4, B5-B4, 0) -> 2 | D5: =IF(B5<B4,B4-B5,0) -> 0 | E5: =$E$18*C5+(1-$E$18)*E4 -> 1.68 | F5: =$E$18*D5+(1-$E$18)*F4 -> 0.16 | G5: =IF(F5=0,1E+307,E5/F5) -> 10.5 | H5: =100-(100/(1+G5)) -> 91.304348
A6: =tsla!A6 -> 45296 | B6: =tsla!B6 -> 102 | C6: =IF(B6>B5, B6-B5, 0) -> 0 | D6: =IF(B6<B5,B5-B6,0) -> 1 | E6: =$E$18*C6+(1-$E$18)*E5 -> 1.344 | F6: =$E$18*D6+(1-$E$18)*F5 -> 0.328 | G6: =IF(F6=0,1E+307,E6/F6) -> 4.097561 | H6: =100-(100/(1+G6)) -> 80.382775
A7: =tsla!A7 -> 45297 | B7: =tsla!B7 -> 104 | C7: =IF(B7>B6, B7-B6, 0) -> 2 | D7: =IF(B7<B6,B6-B7,0) -> 0 | E7: =$E$18*C7+(1-$E$18)*E6 -> 1.4752 | F7: =$E$18*D7+(1-$E$18)*F6 -> 0.2624 | G7: =IF(F7=0,1E+307,E7/F7) -> 5.6219512 | H7: =100-(100/(1+G7)) -> 84.898711
A8: =tsla!A8 -> 45298 | B8: =tsla!B8 -> 106 | C8: =IF(B8>B7, B8-B7, 0) -> 2 | D8: =IF(B8<B7,B7-B8,0) -> 0 | E8: =$E$18*C8+(1-$E$18)*E7 -> 1.58016 | F8: =$E$18*D8+(1-$E$18)*F7 -> 0.20992 | G8: =IF(F8=0,1E+307,E8/F8) -> 7.527439 | H8: =100-(100/(1+G8)) -> 88.27315
A9: =tsla!A9 -> 45299 | B9: =tsla!B9 -> 105 | C9: =IF(B9>B8, B9-B8, 0) -> 0 | D9: =IF(B9<B8,B8-B9,0) -> 1 | E9: =$E$18*C9+(1-$E$18)*E8 -> 1.264128 | F9: =$E$18*D9+(1-$E$18)*F8 -> 0.367936 | G9: =IF(F9=0,1E+307,E9/F9) -> 3.435728 | H9: =100-(100/(1+G9)) -> 77.455786
A10: =tsla!A10 -> 45300 | B10: =tsla!B10 -> 107 | C10: =IF(B10>B9, B10-B9, 0) -> 2 | D10: =IF(B10<B9,B9-B10,0) -> 0 | E10: =$E$18*C10+(1-$E$18)*E9 -> 1.4113024 | F10: =$E$18*D10+(1-$E$18)*F9 -> 0.2943488 | G10: =IF(F10=0,1E+307,E10/F10) -> 4.7946599 | H10: =100-(100/(1+G10)) -> 82.742732
A11: =tsla!A11 -> 45301 | B11: =tsla!B11 -> 108 | C11: =IF(B11>B10, B11-B10, 0) -> 1 | D11: =IF(B11<B10,B10-B11,0) -> 0 | E11: =$E$18*C11+(1-$E$18)*E10 -> 1.3290419 | F11: =$E$18*D11+(1-$E$18)*F10 -> 0.23547904 | G11: =IF(F11=0,1E+307,E11/F11) -> 5.6439924 | H11: =100-(100/(1+G11)) -> 84.948809
A12: =tsla!A12 -> 45302 | B12: =tsla!B12 -> 110 | C12: =IF(B12>B11, B12-B11, 0) -> 2 | D12: =IF(B12<B11,B11-B12,0) -> 0 | E12: =$E$18*C12+(1-$E$18)*E11 -> 1.4632335 | F12: =$E$18*D12+(1-$E$18)*F11 -> 0.18838323 | G12: =IF(F12=0,1E+307,E12/F12) -> 7.7673237 | H12: =100-(100/(1+G12)) -> 88.594011
A13: =tsla!A13 -> 45303 | B13: =tsla!B13 -> 109 | C13: =IF(B13>B12, B13-B12, 0) -> 0 | D13: =IF(B13<B12,B12-B13,0) -> 1 | E13: =$E$18*C13+(1-$E$18)*E12 -> 1.1705868 | F13: =$E$18*D13+(1-$E$18)*F12 -> 0.35070659 | G13: =IF(F13=0,1E+307,E13/F13) -> 3.3377954 | H13: =100-(100/(1+G13)) -> 76.946815
A14: =tsla!A14 -> 45304 | B14: =tsla!B14 -> 111 | C14: =IF(B14>B13, B14-B13, 0) -> 2 | D14: =IF(B14<B13,B13-B14,0) -> 0 | E14: =$E$18*C14+(1-$E$18)*E13 -> 1.3364695 | F14: =$E$18*D14+(1-$E$18)*F13 -> 0.28056527 | G14: =IF(F14=0,1E+307,E14/F14) -> 4.7634886 | H14: =100-(100/(1+G14)) -> 82.649398
A15: =tsla!A15 -> 45305 | B15: =tsla!B15 -> 112 | C15: =IF(B15>B14, B15-B14, 0) -> 1 | D15: =IF(B15<B14,B14-B15,0) -> 0 | E15: =$E$18*C15+(1-$E$18)*E14 -> 1.2691756 | F15: =$E$18*D15+(1-$E$18)*F14 -> 0.22445221 | G15: =IF(F15=0,1E+307,E15/F15) -> 5.6545469 | H15: =100-(100/(1+G15)) -> 84.972681
A16: =tsla!A16 -> 45306 | B16: =tsla!B16 -> 113 | C16: =IF(B16>B15, B16-B15, 0) -> 1 | D16: =IF(B16<B15,B15-B16,0) -> 0 | E16: =$E$18*C16+(1-$E$18)*E15 -> 1.2153405 | F16: =$E$18*D16+(1-$E$18)*F15 -> 0.17956177 | G16: =IF(F16=0,1E+307,E16/F16) -> 6.7683697 | H16: =100-(100/(1+G16)) -> 87.127286
A18: alpha | E18: =1/5 -> 0.2
J19: inf

Sheet stoch_5_3
B1: close | C1: high | D1: low | E1: high_5 | F1: low_5 | G1: k% | H1: d%
A2: =tsla!A2 -> 45292 | B2: =tsla!B2 -> 100 | C2: =tsla!C2 -> 101 | D2: =tsla!D2 -> 99
A3: =tsla!A3 -> 45293 | B3: =tsla!B3 -> 102 | C3: =tsla!C3 -> 103 | D3: =tsla!D3 -> 101
A4: =tsla!A4 -> 45294 | B4: =tsla!B4 -> 101 | C4: =tsla!C4 -> 102 | D4: =tsla!D4 -> 100
A5: =tsla!A5 -> 45295 | B5: =tsla!B5 -> 103 | C5: =tsla!C5 -> 104 | D5: =tsla!D5 -> 102
A6: =tsla!A6 -> 45296 | B6: =tsla!B6 -> 102 | C6: =tsla!C6 -> 103 | D6: =tsla!D6 -> 101 | E6: =MAX(C2:C6) -> 104 | F6: =MIN(D2:D6) -> 99 | G6: =((B6-F6)/(E6-F6))*100 -> 60
A7: =tsla!A7 -> 45297 | B7: =tsla!B7 -> 104 | C7: =tsla!C7 -> 105 | D7: =tsla!D7 -> 103 | E7: =MAX(C3:C7) -> 105 | F7: =MIN(D3:D7) -> 100 | G7: =((B7-F7)/(E7-F7))*100 -> 80
A8: =tsla!A8 -> 45298 | B8: =tsla!B8 -> 106 | C8: =tsla!C8 -> 107 | D8: =tsla!D8 -> 105 | E8: =MAX(C4:C8) -> 107 | F8: =MIN(D4:D8) -> 100 | G8: =((B8-F8)/(E8-F8))*100 -> 85.714286 | H8: =AVERAGE(G6:G8) -> 75.238095
A9: =tsla!A9 -> 45299 | B9: =tsla!B9 -> 105 | C9: =tsla!C9 -> 106 | D9: =tsla!D9 -> 104 | E9: =MAX(C5:C9) -> 107 | F9: =MIN(D5:D9) -> 101 | G9: =((B9-F9)/(E9-F9))*100 -> 66.666667 | H9: =AVERAGE(G7:G9) -> 77.460317
A10: =tsla!A10 -> 45300 | B10: =tsla!B10 -> 107 | C10: =tsla!C10 -> 108 | D10: =tsla!D10 -> 106 | E10: =MAX(C6:C10) -> 108 | F10: =MIN(D6:D10) -> 101 | G10: =((B10-F10)/(E10-F10))*100 -> 85.714286 | H10: =AVERAGE(G8:G10) -> 79.365079
A11: =tsla!A11 -> 45301 | B11: =tsla!B11 -> 108 | C11: =tsla!C11 -> 109 | D11: =tsla!D11 -> 107 | E11: =MAX(C7:C11) -> 109 | F11: =MIN(D7:D11) -> 103 | G11: =((B11-F11)/(E11-F11))*100 -> 83.333333 | H11: =AVERAGE(G9:G11) -> 78.571429
A12: =tsla!A12 -> 45302 | B12: =tsla!B12 -> 110 | C12: =tsla!C12 -> 111 | D12: =tsla!D12 -> 109 | E12: =MAX(C8:C12) -> 111 | F12: =MIN(D8:D12) -> 104 | G12: =((B12-F12)/(E12-F12))*100 -> 85.714286 | H12: =AVERAGE(G10:G12) -> 84.920635
A13: =tsla!A13 -> 45303 | B13: =tsla!B13 -> 109 | C13: =tsla!C13 -> 110 | D13: =tsla!D13 -> 108 | E13: =MAX(C9:C13) -> 111 | F13: =MIN(D9:D13) -> 104 | G13: =((B13-F13)/(E13-F13))*100 -> 71.428571 | H13: =AVERAGE(G11:G13) -> 80.15873
A14: =tsla!A14 -> 45304 | B14: =tsla!B14 -> 111 | C14: =tsla!C14 -> 112 | D14: =tsla!D14 -> 110 | E14: =MAX(C10:C14) -> 112 | F14: =MIN(D10:D14) -> 106 | G14: =((B14-F14)/(E14-F14))*100 -> 83.333333 | H14: =AVERAGE(G12:G14) -> 80.15873
A15: =tsla!A15 -> 45305 | B15: =tsla!B15 -> 112 | C15: =tsla!C15 -> 113 | D15: =tsla!D15 -> 111 | E15: =MAX(C11:C15) -> 113 | F15: =MIN(D11:D15) -> 107 | G15: =((B15-F15)/(E15-F15))*100 -> 83.333333 | H15: =AVERAGE(G13:G15) -> 79.365079
A16: =tsla!A16 -> 45306 | B16: =tsla!B16 -> 113 | C16: =tsla!C16 -> 114 | D16: =tsla!D16 -> 112 | E16: =MAX(C12:C16) -> 114 | F16: =MIN(D12:D16) -> 108 | G16: =((B16-F16)/(E16-F16))*100 -> 83.333333 | H16: =AVERAGE(G14:G16) -> 83.333333

Sheet cci_5_tsla
B1: close | C1: high | D1: low | E1: tp | F1: ma | G1: md | H1: cci
A2: =tsla!A2 -> 45292 | B2: =tsla!B2 -> 100 | C2: =tsla!C2 -> 101 | D2: =tsla!D2 -> 99 | E2: =AVERAGE(B2:D2) -> 100
A3: =tsla!A3 -> 45293 | B3: =tsla!B3 -> 102 | C3: =tsla!C3 -> 103 | D3: =tsla!D3 -> 101 | E3: =AVERAGE(B3:D3) -> 102
A4: =tsla!A4 -> 45294 | B4: =tsla!B4 -> 101 | C4: =tsla!C4 -> 102 | D4: =tsla!D4 -> 100 | E4: =AVERAGE(B4:D4) -> 101
A5: =tsla!A5 -> 45295 | B5: =tsla!B5 -> 103 | C5: =tsla!C5 -> 104 | D5: =tsla!D5 -> 102 | E5: =AVERAGE(B5:D5) -> 103
A6: =tsla!A6 -> 45296 | B6: =tsla!B6 -> 102 | C6: =tsla!C6 -> 103 | D6: =tsla!D6 -> 101 | E6: =AVERAGE(B6:D6) -> 102 | F6: =AVERAGE(E2:E6) -> 101.6 | G6: =AVEDEV(E2:E6) -> 0.88 | H6: =(E6-F6)/(0.015*G6) -> 30.30303
A7: =tsla!A7 -> 45297 | B7: =tsla!B7 -> 104 | C7: =tsla!C7 -> 105 | D7: =tsla!D7 -> 103 | E7: =AVERAGE(B7:D7) -> 104 | F7: =AVERAGE(E3:E7) -> 102.4 | G7: =AVEDEV(E3:E7) -> 0.88 | H7: =(E7-F7)/(0.015*G7) -> 121.21212
A8: =tsla!A8 -> 45298 | B8: =tsla!B8 -> 106 | C8: =tsla!C8 -> 107 | D8: =tsla!D8 -> 105 | E8: =AVERAGE(B8:D8) -> 106 | F8: =AVERAGE(E4:E8) -> 103.2 | G8: =AVEDEV(E4:E8) -> 1.44 | H8: =(E8-F8)/(0.015*G8) -> 129.62963
A9: =tsla!A9 -> 45299 | B9: =tsla!B9 -> 105 | C9: =tsla!C9 -> 106 | D9: =tsla!D9 -> 104 | E9: =AVERAGE(B9:D9) -> 105 | F9: =AVERAGE(E5:E9) -> 104 | G9: =AVEDEV(E5:E9) -> 1.2 | H9: =(E9-F9)/(0.015*G9) -> 55.555556
A10: =tsla!A10 -> 45300 | B10: =tsla!B10 -> 107 | C10: =tsla!C10 -> 108 | D10: =tsla!D10 -> 106 | E10: =AVERAGE(B10:D10) -> 107 | F10: =AVERAGE(E6:E10) -> 104.8 | G10: =AVEDEV(E6:E10) -> 1.44 | H10: =(E10-F10)/(0.015*G10) -> 101.85185
A11: =tsla!A11 -> 45301 | B11: =tsla!B11 -> 108 | C11: =tsla!C11 -> 109 | D11: =tsla!D11 -> 107 | E11: =AVERAGE(B11:D11) -> 108 | F11: =AVERAGE(E7:E11) -> 106 | G11: =AVEDEV(E7:E11) -> 1.2 | H11: =(E11-F11)/(0.015*G11) -> 111.11111
A12: =tsla!A12 -> 45302 | B12: =tsla!B12 -> 110 | C12: =tsla!C12 -> 111 | D12: =tsla!D12 -> 109 | E12: =AVERAGE(B12:D12) -> 110 | F12: =AVERAGE(E8:E12) -> 107.2 | G12: =AVEDEV(E8:E12) -> 1.44 | H12: =(E12-F12)/(0.015*G12) -> 129.62963
A13: =tsla!A13 -> 45303 | B13: =tsla!B13 -> 109 | C13: =tsla!C13 -> 110 | D13: =tsla!D13 -> 108 | E13: =AVERAGE(B13:D13) -> 109 | F13: =AVERAGE(E9:E13) -> 107.8 | G13: =AVEDEV(E9:E13) -> 1.44 | H13: =(E13-F13)/(0.015*G13) -> 55.555556
A14: =tsla!A14 -> 45304 | B14: =tsla!B14 -> 111 | C14: =tsla!C14 -> 112 | D14: =tsla!D14 -> 110 | E14: =AVERAGE(B14:D14) -> 111 | F14: =AVERAGE(E10:E14) -> 109 | G14: =AVEDEV(E10:E14) -> 1.2 | H14: =(E14-F14)/(0.015*G14) -> 111.11111
A15: =tsla!A15 -> 45305 | B15: =tsla!B15 -> 112 | C15: =tsla!C15 -> 113 | D15: =tsla!D15 -> 111 | E15: =AVERAGE(B15:D15) -> 112 | F15: =AVERAGE(E11:E15) -> 110 | G15: =AVEDEV(E11:E15) -> 1.2 | H15: =(E15-F15)/(0.015*G15) -> 111.11111
A16: =tsla!A16 -> 45306 | B16: =tsla!B16 -> 113 | C16: =tsla!C16 -> 114 | D16: =tsla!D16 -> 112 | E16: =AVERAGE(B16:D16) -> 113 | F16: =AVERAGE(E12:E16) -> 111 | G16: =AVEDEV(E12:E16) -> 1.2 | H16: =(E16-F16)/(0.015*G16) -> 111.11111

Sheet momentum_4_tsla
B1: close | C1: shift(4) | D1: momentum
A2: =tsla!A2 -> 45292 | B2: =tsla!B2 -> 100
A3: =tsla!A3 -> 45293 | B3: =tsla!B3 -> 102
A4: =tsla!A4 -> 45294 | B4: =tsla!B4 -> 101
A5: =tsla!A5 -> 45295 | B5: =tsla!B5 -> 103
A6: =tsla!A6 -> 45296 | B6: =tsla!B6 -> 102 | C6: =B2 -> 100 | D6: =B6-C6 -> 2
A7: =tsla!A7 -> 45297 | B7: =tsla!B7 -> 104 | C7: =B3 -> 102 | D7: =B7-C7 -> 2
A8: =tsla!A8 -> 45298 | B8: =tsla!B8 -> 106 | C8: =B4 -> 101 | D8: =B8-C8 -> 5
A9: =tsla!A9 -> 45299 | B9: =tsla!B9 -> 105 | C9: =B5 -> 103 | D9: =B9-C9 -> 2
A10: =tsla!A10 -> 45300 | B10: =tsla!B10 -> 107 | C10: =B6 -> 102 | D10: =B10-C10 -> 5
A11: =tsla!A11 -> 45301 | B11: =tsla!B11 -> 108 | C11: =B7 -> 104 | D11: =B11-C11 -> 4
A12: =tsla!A12 -> 45302 | B12: =tsla!B12 -> 110 | C12: =B8 -> 106 | D12: =B12-C12 -> 4
A13: =tsla!A13 -> 45303 | B13: =tsla!B13 -> 109 | C13: =B9 -> 105 | D13: =B13-C13 -> 4
A14: =tsla!A14 -> 45304 | B14: =tsla!B14 -> 111 | C14: =B10 -> 107 | D14: =B14-C14 -> 4
A15: =tsla!A15 -> 45305 | B15: =tsla!B15 -> 112 | C15: =B11 -> 108 | D15: =B15-C15 -> 4
A16: =tsla!A16 -> 45306 | B16: =tsla!B16 -> 113 | C16: =B12 -> 110 | D16: =B16-C16 -> 3

Sheet daily_return
B1: close | C1: daily_return
A2: =tsla!A2 -> 45292 | B2: =tsla!B2 -> 100
A3: =tsla!A3 -> 45293 | B3: =tsla!B3 -> 102 | C3: =(B3-B2)/B2 -> 0.02
A4: =tsla!A4 -> 45294 | B4: =tsla!B4 -> 101 | C4: =(B4-B3)/B3 -> -0.0098039216
A5: =tsla!A5 -> 45295 | B5: =tsla!B5 -> 103 | C5: =(B5-B4)/B4 -> 0.01980198
A6: =tsla!A6 -> 45296 | B6: =tsla!B6 -> 102 | C6: =(B6-B5)/B5 -> -0.0097087379
A7: =tsla!A7 -> 45297 | B7: =tsla!B7 -> 104 | C7: =(B7-B6)/B6 -> 0.019607843
A8: =tsla!A8 -> 45298 | B8: =tsla!B8 -> 106 | C8: =(B8-B7)/B7 -> 0.019230769
A9: =tsla!A9 -> 45299 | B9: =tsla!B9 -> 105 | C9: =(B9-B8)/B8 -> -0.0094339623
A10: =tsla!A10 -> 45300 | B10: =tsla!B10 -> 107 | C10: =(B10-B9)/B9 -> 0.019047619
A11: =tsla!A11 -> 45301 | B11: =tsla!B11 -> 108 | C11: =(B11-B10)/B10 -> 0.0093457944
A12: =tsla!A12 -> 45302 | B12: =tsla!B12 -> 110 | C12: =(B12-B11)/B11 -> 0.018518519
A13: =tsla!A13 -> 45303 | B13: =tsla!B13 -> 109 | C13: =(B13-B12)/B12 -> -0.0090909091
A14: =tsla!A14 -> 45304 | B14: =tsla!B14 -> 111 | C14: =(B14-B13)/B13 -> 0.018348624
... A16: =tsla!A16 -> 45306 | B16: =tsla!B16 -> 113 | C16: =(B16-B15)/B15 -> 0.0089285714

Sheet cum_return
B1: close | C1: daily_return | D1: cum_return
A2: =tsla!A2 -> 45292 | B2: =tsla!B2 -> 100 | D2: 0
A3: =tsla!A3 -> 45293 | B3: =tsla!B3 -> 102 | C3: =(B3-B2)/B2 -> 0.02 | D3: =(1+C3)*D2+C3 -> 0.02
A4: =tsla!A4 -> 45294 | B4: =tsla!B4 -> 101 | C4: =(B4-B3)/B3 -> -0.0098039216 | D4: =(1+C4)*D3+C4 -> 0.01
A5: =tsla!A5 -> 45295 | B5: =tsla!B5 -> 103 | C5: =(B5-B4)/B4 -> 0.01980198 | D5: =(1+C5)*D4+C5 -> 0.03
A6: =tsla!A6 -> 45296 | B6: =tsla!B6 -> 102 | C6: =(B6-B5)/B5 -> -0.0097087379 | D6: =(1+C6)*D5+C6 -> 0.02
A7: =tsla!A7 -> 45297 | B7: =tsla!B7 -> 104 | C7: =(B7-B6)/B6 -> 0.019607843 | D7: =(1+C7)*D6+C7 -> 0.04
A8: =tsla!A8 -> 45298 | B8: =tsla!B8 -> 106 | C8: =(B8-B7)/B7 -> 0.019230769 | D8: =(1+C8)*D7+C8 -> 0.06
A9: =tsla!A9 -> 45299 | B9: =tsla!B9 -> 105 | C9: =(B9-B8)/B8 -> -0.0094339623 | D9: =(1+C9)*D8+C9 -> 0.05
A10: =tsla!A10 -> 45300 | B10: =tsla!B10 -> 107 | C10: =(B10-B9)/B9 -> 0.019047619 | D10: =(1+C10)*D9+C10 -> 0.07
A11: =tsla!A11 -> 45301 | B11: =tsla!B11 -> 108 | C11: =(B11-B10)/B10 -> 0.0093457944 | D11: =(1+C11)*D10+C11 -> 0.08
A12: =tsla!A12 -> 45302 | B12: =tsla!B12 -> 110 | C12: =(B12-B11)/B11 -> 0.018518519 | D12: =(1+C12)*D11+C12 -> 0.1
A13: =tsla!A13 -> 45303 | B13: =tsla!B13 -> 109 | C13: =(B13-B12)/B12 -> -0.0090909091 | D13: =(1+C13)*D12+C13 -> 0.09
A14: =tsla!A14 -> 45304 | B14: =tsla!B14 -> 111 | C14: =(B14-B13)/B13 -> 0.018348624 | D14: =(1+C14)*D13+C14 -> 0.11
... A16: =tsla!A16 -> 45306 | B16: =tsla!B16 -> 113 | C16: =(B16-B15)/B15 -> 0.0089285714 | D16: =(1+C16)*D15+C16 -> 0.13

Sheet adx_5_20_aapl
B1: close | C1: sma (mid) | D1: stddev | E1: num_std | F1: upper | G1: lower
A2: =aapl!A2 -> 45292 | B2: =aapl!B2 -> 100
A3: =aapl!A3 -> 45293 | B3: =aapl!B3 -> 101
A4: =aapl!A4 -> 45294 | B4: =aapl!B4 -> 102
A5: =aapl!A5 -> 45295 | B5: =aapl!B5 -> 103
A6: =aapl!A6 -> 45296 | B6: =aapl!B6 -> 104 | C6: =AVERAGE(B2:B6) -> 102 | D6: =STDEV((B2:B6)) -> 1.5811388 | E6: 2 | F6: =C6+E6*D6 -> 105.16228 | G6: =C6-E6*D6 -> 98.837722
A7: =aapl!A7 -> 45297 | B7: =aapl!B7 -> 105 | C7: =AVERAGE(B3:B7) -> 103 | D7: =STDEV((B3:B7)) -> 1.5811388 | E7: =E6 -> 2 | F7: =C7+E7*D7 -> 106.16228 | G7: =C7-E7*D7 -> 99.837722
A8: =aapl!A8 -> 45298 | B8: =aapl!B8 -> 106 | C8: =AVERAGE(B4:B8) -> 104 | D8: =STDEV((B4:B8)) -> 1.5811388 | E8: =E7 -> 2 | F8: =C8+E8*D8 -> 107.16228 | G8: =C8-E8*D8 -> 100.83772
A9: =aapl!A9 -> 45299 | B9: =aapl!B9 -> 107 | C9: =AVERAGE(B5:B9) -> 105 | D9: =STDEV((B5:B9)) -> 1.5811388 | E9: =E8 -> 2 | F9: =C9+E9*D9 -> 108.16228 | G9: =C9-E9*D9 -> 101.83772
A10: =aapl!A10 -> 45300 | B10: =aapl!B10 -> 108 | C10: =AVERAGE(B6:B10) -> 106 | D10: =STDEV((B6:B10)) -> 1.5811388 | E10: =E9 -> 2 | F10: =C10+E10*D10 -> 109.16228 | G10: =C10-E10*D10 -> 102.83772
A11: =aapl!A11 -> 45301 | B11: =aapl!B11 -> 109 | C11: =AVERAGE(B7:B11) -> 107 | D11: =STDEV((B7:B11)) -> 1.5811388 | E11: =E10 -> 2 | F11: =C11+E11*D11 -> 110.16228 | G11: =C11-E11*D11 -> 103.83772

Sheet tr_tsla
B1: close | C1: high | D1: low | E1: prev_close | F1: high-low | G1: high-prev_close | H1: low - prev_close | I1: tr
A2: =tsla!A2 -> 45292 | B2: =tsla!B2 -> 100 | C2: =tsla!C2 -> 101 | D2: =tsla!D2 -> 99 | F2: =C2-D2 -> 2 | I2: =MAX(F2:H2) -> 2
A3: =tsla!A3 -> 45293 | B3: =tsla!B3 -> 102 | C3: =tsla!C3 -> 103 | D3: =tsla!D3 -> 101 | E3: =B2 -> 100 | F3: =C3-D3 -> 2 | G3: =C3-E3 -> 3 | H3: =D3-E3 -> 1 | I3: =MAX(F3:H3) -> 3
A4: =tsla!A4 -> 45294 | B4: =tsla!B4 -> 101 | C4: =tsla!C4 -> 102 | D4: =tsla!D4 -> 100 | E4: =B3 -> 102 | F4: =C4-D4 -> 2 | G4: =C4-E4 -> 0 | H4: =D4-E4 -> -2 | I4: =MAX(F4:H4) -> 2
A5: =tsla!A5 -> 45295 | B5: =tsla!B5 -> 103 | C5: =tsla!C5 -> 104 | D5: =tsla!D5 -> 102 | E5: =B4 -> 101 | F5: =C5-D5 -> 2 | G5: =C5-E5 -> 3 | H5: =D5-E5 -> 1 | I5: =MAX(F5:H5) -> 3
A6: =tsla!A6 -> 45296 | B6: =tsla!B6 -> 102 | C6: =tsla!C6 -> 103 | D6: =tsla!D6 -> 101 | E6: =B5 -> 103 | F6: =C6-D6 -> 2 | G6: =C6-E6 -> 0 | H6: =D6-E6 -> -2 | I6: =MAX(F6:H6) -> 2
A7: =tsla!A7 -> 45297 | B7: =tsla!B7 -> 104 | C7: =tsla!C7 -> 105 | D7: =tsla!D7 -> 103 | E7: =B6 -> 102 | F7: =C7-D7 -> 2 | G7: =C7-E7 -> 3 | H7: =D7-E7 -> 1 | I7: =MAX(F7:H7) -> 3
A8: =tsla!A8 -> 45298 | B8: =tsla!B8 -> 106 | C8: =tsla!C8 -> 107 | D8: =tsla!D8 -> 105 | E8: =B7 -> 104 | F8: =C8-D8 -> 2 | G8: =C8-E8 -> 3 | H8: =D8-E8 -> 1 | I8: =MAX(F8:H8) -> 3
A9: =tsla!A9 -> 45299 | B9: =tsla!B9 -> 105 | C9: =tsla!C9 -> 106 | D9: =tsla!D9 -> 104 | E9: =B8 -> 106 | F9: =C9-D9 -> 2 | G9: =C9-E9 -> 0 | H9: =D9-E9 -> -2 | I9: =MAX(F9:H9) -> 2
A10: =tsla!A10 -> 45300 | B10: =tsla!B10 -> 107 | C10: =tsla!C10 -> 108 | D10: =tsla!D10 -> 106 | E10: =B9 -> 105 | F10: =C10-D10 -> 2 | G10: =C10-E10 -> 3 | H10: =D10-E10 -> 1 | I10: =MAX(F10:H10) -> 3
A11: =tsla!A11 -> 45301 | B11: =tsla!B11 -> 108 | C11: =tsla!C11 -> 109 | D11: =tsla!D11 -> 107 | E11: =B10 -> 107 | F11: =C11-D11 -> 2 | G11: =C11-E11 -> 2 | H11: =D11-E11 -> 0 | I11: =MAX(F11:H11) -> 2
A12: =tsla!A12 -> 45302 | B12: =tsla!B12 -> 110 | C12: =tsla!C12 -> 111 | D12: =tsla!D12 -> 109 | E12: =B11 -> 108 | F12: =C12-D12 -> 2 | G12: =C12-E12 -> 3 | H12: =D12-E12 -> 1 | I12: =MAX(F12:H12) -> 3
A13: =tsla!A13 -> 45303 | B13: =tsla!B13 -> 109 | C13: =tsla!C13 -> 110 | D13: =tsla!D13 -> 108 | E13: =B12 -> 110 | F13: =C13-D13 -> 2 | G13: =C13-E13 -> 0 | H13: =D13-E13 -> -2 | I13: =MAX(F13:H13) -> 2
A14: =tsla!A14 -> 45304 | B14: =tsla!B14 -> 111 | C14: =tsla!C14 -> 112 | D14: =tsla!D14 -> 110 | E14: =B13 -> 109 | F14: =C14-D14 -> 2 | G14: =C14-E14 -> 3 | H14: =D14-E14 -> 1 | I14: =MAX(F14:H14) -> 3
... A16: =tsla!A16 -> 45306 | B16: =tsla!B16 -> 113 | C16: =tsla!C16 -> 114 | D16: =tsla!D16 -> 112 | E16: =B15 -> 112 | F16: =C16-D16 -> 2 | G16: =C16-E16 -> 2 | H16: =D16-E16 -> 0 | I16: =MAX(F16:H16) -> 2

Sheet atr_tsla
B1: close | C1: high | D1: low | E1: prev_close | F1: high-low | G1: high-prev_close | H1: low - prev_close | I1: tr | J1: atr_5
A2: =tsla!A2 -> 45292 | B2: =tsla!B2 -> 100 | C2: =tsla!C2 -> 101 | D2: =tsla!D2 -> 99 | F2: =C2-D2 -> 2 | I2: =MAX(F2:H2) -> 2
A3: =tsla!A3 -> 45293 | B3: =tsla!B3 -> 102 | C3: =tsla!C3 -> 103 | D3: =tsla!D3 -> 101 | E3: =B2 -> 100 | F3: =C3-D3 -> 2 | G3: =C3-E3 -> 3 | H3: =D3-E3 -> 1 | I3: =MAX(F3:H3) -> 3
A4: =tsla!A4 -> 45294 | B4: =tsla!B4 -> 101 | C4: =tsla!C4 -> 102 | D4: =tsla!D4 -> 100 | E4: =B3 -> 102 | F4: =C4-D4 -> 2 | G4: =C4-E4 -> 0 | H4: =D4-E4 -> -2 | I4: =MAX(F4:H4) -> 2
A5: =tsla!A5 -> 45295 | B5: =tsla!B5 -> 103 | C5: =tsla!C5 -> 104 | D5: =tsla!D5 -> 102 | E5: =B4 -> 101 | F5: =C5-D5 -> 2 | G5: =C5-E5 -> 3 | H5: =D5-E5 -> 1 | I5: =MAX(F5:H5) -> 3
A6: =tsla!A6 -> 45296 | B6: =tsla!B6 -> 102 | C6: =tsla!C6 -> 103 | D6: =tsla!D6 -> 101 | E6: =B5 -> 103 | F6: =C6-D6 -> 2 | G6: =C6-E6 -> 0 | H6: =D6-E6 -> -2 | I6: =MAX(F6:H6) -> 2 | J6: =AVERAGE(I2:I6) -> 2.4
A7: =tsla!A7 -> 45297 | B7: =tsla!B7 -> 104 | C7: =tsla!C7 -> 105 | D7: =tsla!D7 -> 103 | E7: =B6 -> 102 | F7: =C7-D7 -> 2 | G7: =C7-E7 -> 3 | H7: =D7-E7 -> 1 | I7: =MAX(F7:H7) -> 3 | J7: =AVERAGE(I3:I7) -> 2.6
A8: =tsla!A8 -> 45298 | B8: =tsla!B8 -> 106 | C8: =tsla!C8 -> 107 | D8: =tsla!D8 -> 105 | E8: =B7 -> 104 | F8: =C8-D8 -> 2 | G8: =C8-E8 -> 3 | H8: =D8-E8 -> 1 | I8: =MAX(F8:H8) -> 3 | J8: =AVERAGE(I4:I8) -> 2.6
A9: =tsla!A9 -> 45299 | B9: =tsla!B9 -> 105 | C9: =tsla!C9 -> 106 | D9: =tsla!D9 -> 104 | E9: =B8 -> 106 | F9: =C9-D9 -> 2 | G9: =C9-E9 -> 0 | H9: =D9-E9 -> -2 | I9: =MAX(F9:H9) -> 2 | J9: =AVERAGE(I5:I9) -> 2.6
A10: =tsla!A10 -> 45300 | B10: =tsla!B10 -> 107 | C10: =tsla!C10 -> 108 | D10: =tsla!D10 -> 106 | E10: =B9 -> 105 | F10: =C10-D10 -> 2 | G10: =C10-E10 -> 3 | H10: =D10-E10 -> 1 | I10: =MAX(F10:H10) -> 3 | J10: =AVERAGE(I6:I10) -> 2.6
A11: =tsla!A11 -> 45301 | B11: =tsla!B11 -> 108 | C11: =tsla!C11 -> 109 | D11: =tsla!D11 -> 107 | E11: =B10 -> 107 | F11: =C11-D11 -> 2 | G11: =C11-E11 -> 2 | H11: =D11-E11 -> 0 | I11: =MAX(F11:H11) -> 2 | J11: =AVERAGE(I7:I11) -> 2.6
A12: =tsla!A12 -> 45302 | B12: =tsla!B12 -> 110 | C12: =tsla!C12 -> 111 | D12: =tsla!D12 -> 109 | E12: =B11 -> 108 | F12: =C12-D12 -> 2 | G12: =C12-E12 -> 3 | H12: =D12-E12 -> 1 | I12: =MAX(F12:H12) -> 3 | J12: =AVERAGE(I8:I12) -> 2.6
A13: =tsla!A13 -> 45303 | B13: =tsla!B13 -> 109 | C13: =tsla!C13 -> 110 | D13: =tsla!D13 -> 108 | E13: =B12 -> 110 | F13: =C13-D13 -> 2 | G13: =C13-E13 -> 0 | H13: =D13-E13 -> -2 | I13: =MAX(F13:H13) -> 2 | J13: =AVERAGE(I9:I13) -> 2.4
A14: =tsla!A14 -> 45304 | B14: =tsla!B14 -> 111 | C14: =tsla!C14 -> 112 | D14: =tsla!D14 -> 110 | E14: =B13 -> 109 | F14: =C14-D14 -> 2 | G14: =C14-E14 -> 3 | H14: =D14-E14 -> 1 | I14: =MAX(F14:H14) -> 3 | J14: =AVERAGE(I10:I14) -> 2.6
A15: =tsla!A15 -> 45305 | B15: =tsla!B15 -> 112 | C15: =tsla!C15 -> 113 | D15: =tsla!D15 -> 111 | E15: =B14 -> 111 | F15: =C15-D15 -> 2 | G15: =C15-E15 -> 2 | H15: =D15-E15 -> 0 | I15: =MAX(F15:H15) -> 2 | J15: =AVERAGE(I11:I15) -> 2.4
A16: =tsla!A16 -> 45306 | B16: =tsla!B16 -> 113 | C16: =tsla!C16 -> 114 | D16: =tsla!D16 -> 112 | E16: =B15 -> 112 | F16: =C16-D16 -> 2 | G16: =C16-E16 -> 2 | H16: =D16-E16 -> 0 | I16: =MAX(F16:H16) -> 2 | J16: =AVERAGE(I12:I16) -> 2.4

Sheet stddev_5_tsla
B1: close | C1: stddev_5
A2: =tsla!A2 -> 45292 | B2: =tsla!B2 -> 100
A3: =tsla!A3 -> 45293 | B3: =tsla!B3 -> 102
A4: =tsla!A4 -> 45294 | B4: =tsla!B4 -> 101
A5: =tsla!A5 -> 45295 | B5: =tsla!B5 -> 103
A6: =tsla!A6 -> 45296 | B6: =tsla!B6 -> 102 | C6: =STDEV(B2:B6) -> 1.1401754
A7: =tsla!A7 -> 45297 | B7: =tsla!B7 -> 104 | C7: =STDEV(B3:B7) -> 1.1401754
A8: =tsla!A8 -> 45298 | B8: =tsla!B8 -> 106 | C8: =STDEV(B4:B8) -> 1.9235384
A9: =tsla!A9 -> 45299 | B9: =tsla!B9 -> 105 | C9: =STDEV(B5:B9) -> 1.5811388
A10: =tsla!A10 -> 45300 | B10: =tsla!B10 -> 107 | C10: =STDEV(B6:B10) -> 1.9235384
A11: =tsla!A11 -> 45301 | B11: =tsla!B11 -> 108 | C11: =STDEV(B7:B11) -> 1.5811388
A12: =tsla!A12 -> 45302 | B12: =tsla!B12 -> 110 | C12: =STDEV(B8:B12) -> 1.9235384
A13: =tsla!A13 -> 45303 | B13: =tsla!B13 -> 109 | C13: =STDEV(B9:B13) -> 1.9235384
A14: =tsla!A14 -> 45304 | B14: =tsla!B14 -> 111 | C14: =STDEV(B10:B14) -> 1.5811388
A15: =tsla!A15 -> 45305 | B15: =tsla!B15 -> 112 | C15: =STDEV(B11:B15) -> 1.5811388
A16: =tsla!A16 -> 45306 | B16: =tsla!B16 -> 113 | C16: =STDEV(B12:B16) -> 1.5811388

Sheet vsma_5_aapl
B1: close | C1: =aapl!E1 -> volume | D1: vsma_5
A2: =aapl!A2 -> 45292 | B2: =aapl!B2 -> 100 | C2: =aapl!E2 -> 1000
A3: =A2+1 -> 45293 | B3: =aapl!B3 -> 101 | C3: =aapl!E3 -> 1010
A4: =A3+1 -> 45294 | B4: =aapl!B4 -> 102 | C4: =aapl!E4 -> 1020
A5: =A4+1 -> 45295 | B5: =aapl!B5 -> 103 | C5: =aapl!E5 -> 1030
A6: =A5+1 -> 45296 | B6: =aapl!B6 -> 104 | C6: =aapl!E6 -> 1040 | D6: =AVERAGE(C2:C6) -> 1020
A7: =A6+1 -> 45297 | B7: =aapl!B7 -> 105 | C7: =aapl!E7 -> 1050 | D7: =AVERAGE(C3:C7) -> 1030
A8: =A7+1 -> 45298 | B8: =aapl!B8 -> 106 | C8: =aapl!E8 -> 1060 | D8: =AVERAGE(C4:C8) -> 1040
A9: =A8+1 -> 45299 | B9: =aapl!B9 -> 107 | C9: =aapl!E9 -> 1070 | D9: =AVERAGE(C5:C9) -> 1050
A10: =A9+1 -> 45300 | B10: =aapl!B10 -> 108 | C10: =aapl!E10 -> 1080 | D10: =AVERAGE(C6:C10) -> 1060
A11: =A10+1 -> 45301 | B11: =aapl!B11 -> 109 | C11: =aapl!E11 -> 1090 | D11: =AVERAGE(C7:C11) -> 1070

Sheet vema_5_aapl
B1: close | C1: =aapl!E1 -> volume | D1: vewm_5
A2: =aapl!A2 -> 45292 | B2: =aapl!B2 -> 100 | C2: =aapl!E2 -> 1000 | D2: =C2 -> 1000
A3: =A2+1 -> 45293 | B3: =aapl!B3 -> 101 | C3: =aapl!E3 -> 1010 | D3: =C3*$D$14+D2*(1-$D$14) -> 1003.3333
A4: =A3+1 -> 45294 | B4: =aapl!B4 -> 102 | C4: =aapl!E4 -> 1020 | D4: =C4*$D$14+D3*(1-$D$14) -> 1008.8889
A5: =A4+1 -> 45295 | B5: =aapl!B5 -> 103 | C5: =aapl!E5 -> 1030 | D5: =C5*$D$14+D4*(1-$D$14) -> 1015.9259
A6: =A5+1 -> 45296 | B6: =aapl!B6 -> 104 | C6: =aapl!E6 -> 1040 | D6: =C6*$D$14+D5*(1-$D$14) -> 1023.9506
A7: =A6+1 -> 45297 | B7: =aapl!B7 -> 105 | C7: =aapl!E7 -> 1050 | D7: =C7*$D$14+D6*(1-$D$14) -> 1032.6337
A8: =A7+1 -> 45298 | B8: =aapl!B8 -> 106 | C8: =aapl!E8 -> 1060 | D8: =C8*$D$14+D7*(1-$D$14) -> 1041.7558
A9: =A8+1 -> 45299 | B9: =aapl!B9 -> 107 | C9: =aapl!E9 -> 1070 | D9: =C9*$D$14+D8*(1-$D$14) -> 1051.1706
A10: =A9+1 -> 45300 | B10: =aapl!B10 -> 108 | C10: =aapl!E10 -> 1080 | D10: =C10*$D$14+D9*(1-$D$14) -> 1060.7804
A11: =A10+1 -> 45301 | B11: =aapl!B11 -> 109 | C11: =aapl!E11 -> 1090 | D11: =C11*$D$14+D10*(1-$D$14) -> 1070.5202
A13: span | D13: 5
A14: alpha | D14: =2/(D13+1) -> 0.33333333

Sheet pvt_tsla
B1: =tsla!B1 -> close | C1: =tsla!E1 -> volume | D1: pct_change | E1: pct_change x volume | F1: pvt
A2: =tsla!A2 -> 45292 | B2: =tsla!B2 -> 100 | C2: =tsla!E2 -> 1000 | E2: 0 | F2: =E2 -> 0
A3: =tsla!A3 -> 45293 | B3: =tsla!B3 -> 102 | C3: =tsla!E3 -> 950 | D3: =(B3/B2)-1 -> 0.02 | E3: =C3*D3 -> 19 | F3: =F2+E3 -> 19
A4: =tsla!A4 -> 45294 | B4: =tsla!B4 -> 101 | C4: =tsla!E4 -> 990 | D4: =(B4/B3)-1 -> -0.0098039216 | E4: =C4*D4 -> -9.7058824 | F4: =F3+E4 -> 9.2941176
A5: =tsla!A5 -> 45295 | B5: =tsla!B5 -> 103 | C5: =tsla!E5 -> 1020 | D5: =(B5/B4)-1 -> 0.01980198 | E5: =C5*D5 -> 20.19802 | F5: =F4+E5 -> 29.492137
A6: =tsla!A6 -> 45296 | B6: =tsla!B6 -> 102 | C6: =tsla!E6 -> 1100 | D6: =(B6/B5)-1 -> -0.0097087379 | E6: =C6*D6 -> -10.679612 | F6: =F5+E6 -> 18.812526
A7: =tsla!A7 -> 45297 | B7: =tsla!B7 -> 104 | C7: =tsla!E7 -> 900 | D7: =(B7/B6)-1 -> 0.019607843 | E7: =C7*D7 -> 17.647059 | F7: =F6+E7 -> 36.459585
A8: =tsla!A8 -> 45298 | B8: =tsla!B8 -> 106 | C8: =tsla!E8 -> 980 | D8: =(B8/B7)-1 -> 0.019230769 | E8: =C8*D8 -> 18.846154 | F8: =F7+E8 -> 55.305738
A9: =tsla!A9 -> 45299 | B9: =tsla!B9 -> 105 | C9: =tsla!E9 -> 1030 | D9: =(B9/B8)-1 -> -0.0094339623 | E9: =C9*D9 -> -9.7169811 | F9: =F8+E9 -> 45.588757
A10: =tsla!A10 -> 45300 | B10: =tsla!B10 -> 107 | C10: =tsla!E10 -> 1100 | D10: =(B10/B9)-1 -> 0.019047619 | E10: =C10*D10 -> 20.952381 | F10: =F9+E10 -> 66.541138
A11: =tsla!A11 -> 45301 | B11: =tsla!B11 -> 108 | C11: =tsla!E11 -> 1080 | D11: =(B11/B10)-1 -> 0.0093457944 | E11: =C11*D11 -> 10.093458 | F11: =F10+E11 -> 76.634596
A12: =tsla!A12 -> 45302 | B12: =tsla!B12 -> 110 | C12: =tsla!E12 -> 975 | D12: =(B12/B11)-1 -> 0.018518519 | E12: =C12*D12 -> 18.055556 | F12: =F11+E12 -> 94.690152
A13: =tsla!A13 -> 45303 | B13: =tsla!B13 -> 109 | C13: =tsla!E13 -> 1010 | D13: =(B13/B12)-1 -> -0.0090909091 | E13: =C13*D13 -> -9.1818182 | F13: =F12+E13 -> 85.508334
A14: =tsla!A14 -> 45304 | B14: =tsla!B14 -> 111 | C14: =tsla!E14 -> 1110 | D14: =(B14/B13)-1 -> 0.018348624 | E14: =C14*D14 -> 20.366972 | F14: =F13+E14 -> 105.87531
... A16: =tsla!A16 -> 45306 | B16: =tsla!B16 -> 113 | C16: =tsla!E16 -> 1130 | D16: =(B16/B15)-1 -> 0.0089285714 | E16: =C16*D16 -> 10.089286 | F16: =F15+E16 -> 125.42405

Sheet obv_tsla
B1: =tsla!B1 -> close | C1: =tsla!E1 -> volume | D1: diff | E1: direction | F1: volume x direction | G1: obv
A2: =tsla!A2 -> 45292 | B2: =tsla!B2 -> 100 | C2: =tsla!E2 -> 1000 | G2: 0
A3: =tsla!A3 -> 45293 | B3: =tsla!B3 -> 102 | C3: =tsla!E3 -> 950 | D3: =B3-B2 -> 2 | E3: =IF(D3>0,1,IF(D3<0, -1, 0)) -> 1 | F3: =C3*E3 -> 950 | G3: =F3+G2 -> 950
A4: =tsla!A4 -> 45294 | B4: =tsla!B4 -> 101 | C4: =tsla!E4 -> 990 | D4: =B4-B3 -> -1 | E4: =IF(D4>0,1,IF(D4<0, -1, 0)) -> -1 | F4: =C4*E4 -> -990 | G4: =F4+G3 -> -40
A5: =tsla!A5 -> 45295 | B5: =tsla!B5 -> 103 | C5: =tsla!E5 -> 1020 | D5: =B5-B4 -> 2 | E5: =IF(D5>0,1,IF(D5<0, -1, 0)) -> 1 | F5: =C5*E5 -> 1020 | G5: =F5+G4 -> 980
A6: =tsla!A6 -> 45296 | B6: =tsla!B6 -> 102 | C6: =tsla!E6 -> 1100 | D6: =B6-B5 -> -1 | E6: =IF(D6>0,1,IF(D6<0, -1, 0)) -> -1 | F6: =C6*E6 -> -1100 | G6: =F6+G5 -> -120
A7: =tsla!A7 -> 45297 | B7: =tsla!B7 -> 104 | C7: =tsla!E7 -> 900 | D7: =B7-B6 -> 2 | E7: =IF(D7>0,1,IF(D7<0, -1, 0)) -> 1 | F7: =C7*E7 -> 900 | G7: =F7+G6 -> 780
A8: =tsla!A8 -> 45298 | B8: =tsla!B8 -> 106 | C8: =tsla!E8 -> 980 | D8: =B8-B7 -> 2 | E8: =IF(D8>0,1,IF(D8<0, -1, 0)) -> 1 | F8: =C8*E8 -> 980 | G8: =F8+G7 -> 1760
A9: =tsla!A9 -> 45299 | B9: =tsla!B9 -> 105 | C9: =tsla!E9 -> 1030 | D9: =B9-B8 -> -1 | E9: =IF(D9>0,1,IF(D9<0, -1, 0)) -> -1 | F9: =C9*E9 -> -1030 | G9: =F9+G8 -> 730
A10: =tsla!A10 -> 45300 | B10: =tsla!B10 -> 107 | C10: =tsla!E10 -> 1100 | D10: =B10-B9 -> 2 | E10: =IF(D10>0,1,IF(D10<0, -1, 0)) -> 1 | F10: =C10*E10 -> 1100 | G10: =F10+G9 -> 1830
A11: =tsla!A11 -> 45301 | B11: =tsla!B11 -> 108 | C11: =tsla!E11 -> 1080 | D11: =B11-B10 -> 1 | E11: =IF(D11>0,1,IF(D11<0, -1, 0)) -> 1 | F11: =C11*E11 -> 1080 | G11: =F11+G10 -> 2910
A12: =tsla!A12 -> 45302 | B12: =tsla!B12 -> 110 | C12: =tsla!E12 -> 975 | D12: =B12-B11 -> 2 | E12: =IF(D12>0,1,IF(D12<0, -1, 0)) -> 1 | F12: =C12*E12 -> 975 | G12: =F12+G11 -> 3885
A13: =tsla!A13 -> 45303 | B13: =tsla!B13 -> 109 | C13: =tsla!E13 -> 1010 | D13: =B13-B12 -> -1 | E13: =IF(D13>0,1,IF(D13<0, -1, 0)) -> -1 | F13: =C13*E13 -> -1010 | G13: =F13+G12 -> 2875
A14: =tsla!A14 -> 45304 | B14: =tsla!B14 -> 111 | C14: =tsla!E14 -> 1110 | D14: =B14-B13 -> 2 | E14: =IF(D14>0,1,IF(D14<0, -1, 0)) -> 1 | F14: =C14*E14 -> 1110 | G14: =F14+G13 -> 3985
... A16: =tsla!A16 -> 45306 | B16: =tsla!B16 -> 113 | C16: =tsla!E16 -> 1130 | D16: =B16-B15 -> 1 | E16: =IF(D16>0,1,IF(D16<0, -1, 0)) -> 1 | F16: =C16*E16 -> 1130 | G16: =F16+G15 -> 6165

Sheet cmf_5_tsla
B1: =tsla!B1 -> close | D1: =tsla!C1 -> high | E1: =tsla!D1 -> low | F1: =tsla!E1 -> volume | G1: denom | H1: close-low | I1: high-close | J1: clv | K1: clv x volume | L1: avg clv x vol | M1: avg vol | N1: cmf_5
A2: =tsla!A2 -> 45292 | B2: =tsla!B2 -> 100 | C2: 0 | D2: =tsla!C2+C2 -> 101 | E2: =tsla!D2 -> 99 | F2: =tsla!E2 -> 1000 | G2: =D2-E2 -> 2 | H2: =B2-E2 -> 1 | I2: =D2-B2 -> 1 | J2: =(H2-I2)/G2 -> 0 | K2: =J2*F2 -> 0
A3: =tsla!A3 -> 45293 | B3: =tsla!B3 -> 102 | C3: =C2+0.5 -> 0.5 | D3: =tsla!C3+C3 -> 103.5 | E3: =tsla!D3 -> 101 | F3: =tsla!E3 -> 950 | G3: =D3-E3 -> 2.5 | H3: =B3-E3 -> 1 | I3: =D3-B3 -> 1.5 | J3: =(H3-I3)/G3 -> -0.2 | K3: =J3*F3 -> -190
A4: =tsla!A4 -> 45294 | B4: =tsla!B4 -> 101 | C4: =C3+0.5 -> 1 | D4: =tsla!C4+C4 -> 103 | E4: =tsla!D4 -> 100 | F4: =tsla!E4 -> 990 | G4: =D4-E4 -> 3 | H4: =B4-E4 -> 1 | I4: =D4-B4 -> 2 | J4: =(H4-I4)/G4 -> -0.33333333 | K4: =J4*F4 -> -330
A5: =tsla!A5 -> 45295 | B5: =tsla!B5 -> 103 | C5: =C4+0.5 -> 1.5 | D5: =tsla!C5+C5 -> 105.5 | E5: =tsla!D5 -> 102 | F5: =tsla!E5 -> 1020 | G5: =D5-E5 -> 3.5 | H5: =B5-E5 -> 1 | I5: =D5-B5 -> 2.5 | J5: =(H5-I5)/G5 -> -0.42857143 | K5: =J5*F5 -> -437.14286
A6: =tsla!A6 -> 45296 | B6: =tsla!B6 -> 102 | C6: =C5+0.5 -> 2 | D6: =tsla!C6+C6 -> 105 | E6: =tsla!D6 -> 101 | F6: =tsla!E6 -> 1100 | G6: =D6-E6 -> 4 | H6: =B6-E6 -> 1 | I6: =D6-B6 -> 3 | J6: =(H6-I6)/G6 -> -0.5 | K6: =J6*F6 -> -550 | L6: =AVERAGE(K2:K6) -> -301.42857 | M6: =AVERAGE(F2:F6) -> 1012 | N6: =L6/M6 -> -0.29785432
A7: =tsla!A7 -> 45297 | B7: =tsla!B7 -> 104 | C7: =C6+0.5 -> 2.5 | D7: =tsla!C7+C7 -> 107.5 | E7: =tsla!D7 -> 103 | F7: =tsla!E7 -> 900 | G7: =D7-E7 -> 4.5 | H7: =B7-E7 -> 1 | I7: =D7-B7 -> 3.5 | J7: =(H7-I7)/G7 -> -0.55555556 | K7: =J7*F7 -> -500 | L7: =AVERAGE(K3:K7) -> -401.42857 | M7: =AVERAGE(F3:F7) -> 992 | N7: =L7/M7 -> -0.4046659
A8: =tsla!A8 -> 45298 | B8: =tsla!B8 -> 106 | C8: =C7+0.5 -> 3 | D8: =tsla!C8+C8 -> 110 | E8: =tsla!D8 -> 105 | F8: =tsla!E8 -> 980 | G8: =D8-E8 -> 5 | H8: =B8-E8 -> 1 | I8: =D8-B8 -> 4 | J8: =(H8-I8)/G8 -> -0.6 | K8: =J8*F8 -> -588 | L8: =AVERAGE(K4:K8) -> -481.02857 | M8: =AVERAGE(F4:F8) -> 998 | N8: =L8/M8 -> -0.48199256
A9: =tsla!A9 -> 45299 | B9: =tsla!B9 -> 105 | C9: =C8+0.5 -> 3.5 | D9: =tsla!C9+C9 -> 109.5 | E9: =tsla!D9 -> 104 | F9: =tsla!E9 -> 1030 | G9: =D9-E9 -> 5.5 | H9: =B9-E9 -> 1 | I9: =D9-B9 -> 4.5 | J9: =(H9-I9)/G9 -> -0.63636364 | K9: =J9*F9 -> -655.45455 | L9: =AVERAGE(K5:K9) -> -546.11948 | M9: =AVERAGE(F5:F9) -> 1006 | N9: =L9/M9 -> -0.54286231
A10: =tsla!A10 -> 45300 | B10: =tsla!B10 -> 107 | C10: =C9+0.5 -> 4 | D10: =tsla!C10+C10 -> 112 | E10: =tsla!D10 -> 106 | F10: =tsla!E10 -> 1100 | G10: =D10-E10 -> 6 | H10: =B10-E10 -> 1 | I10: =D10-B10 -> 5 | J10: =(H10-I10)/G10 -> -0.66666667 | K10: =J10*F10 -> -733.33333 | L10: =AVERAGE(K6:K10) -> -605.35758 | M10: =AVERAGE(F6:F10) -> 1022 | N10: =L10/M10 -> -0.5923264
A11: =tsla!A11 -> 45301 | B11: =tsla!B11 -> 108 | C11: =C10+0.5 -> 4.5 | D11: =tsla!C11+C11 -> 113.5 | E11: =tsla!D11 -> 107 | F11: =tsla!E11 -> 1080 | G11: =D11-E11 -> 6.5 | H11: =B11-E11 -> 1 | I11: =D11-B11 -> 5.5 | J11: =(H11-I11)/G11 -> -0.69230769 | K11: =J11*F11 -> -747.69231 | L11: =AVERAGE(K7:K11) -> -644.89604 | M11: =AVERAGE(F7:F11) -> 1018 | N11: =L11/M11 -> -0.63349316
A12: =tsla!A12 -> 45302 | B12: =tsla!B12 -> 110 | C12: =C11+0.5 -> 5 | D12: =tsla!C12+C12 -> 116 | E12: =tsla!D12 -> 109 | F12: =tsla!E12 -> 975 | G12: =D12-E12 -> 7 | H12: =B12-E12 -> 1 | I12: =D12-B12 -> 6 | J12: =(H12-I12)/G12 -> -0.71428571 | K12: =J12*F12 -> -696.42857 | L12: =AVERAGE(K8:K12) -> -684.18175 | M12: =AVERAGE(F8:F12) -> 1033 | N12: =L12/M12 -> -0.66232503
